Workbook
Name StrMod: '角色卡'!$J$15
Name WisMod: '角色卡'!$J$19
Name Cha: '角色卡'!$G$20
Name Str: '角色卡'!$G$15
Name DexMod: '角色卡'!$J$16
Name Int: '角色卡'!$G$18
Name tweight: '裝備與物品'!$AB$34
Name Con: '角色卡'!$G$17
Name Dex: '角色卡'!$G$16
Name AC: '角色卡'!$AN$27
Name Lvl: '角色卡'!$Q$7
Name Wis: '角色卡'!$G$19
Name Prof: '角色卡'!$C$47
Name Lvsum: #REF!
Name tweight: #REF!
Name ConMod: '角色卡'!$J$17
Name ChaMod: '角色卡'!$J$20
Name IntMod: '角色卡'!$J$18

Sheet 請先閱讀
Q1: 更新LOG | R1: 45562 | S1: 1.0 | T1: 角色卡完成 | V1: 45994 | W1: 3.0d | X1: 。加入資源《艾伯倫：奇械師的鍛造爐》堡壘設施
B2: 。前言。 | K2: 身高換算 | R2: 45564 | S2: 1.1 | T2: 。新增更新Log、英雄激勵、護甲選項自動化 。調整了先攻加值的位置 。移除了角色關係，改為陣營及能力值特質 | V2: 45996 | W2: 3.0.1 | X2: 。修正了奇械師未顯示生命骰的問題 。修正了年齡欄位會出現體重單位的問題 。修正了奇械師無法出現在法術表來源的問題
L3: 公分 | M3: =ROUNDDOWN(K3/(2.54*12),0) -> 0 | N3: 呎 | R3: 45568 | S3: 1.2 | T3: 。新增金錢紀錄表、施法等級、召喚物先攻 。法術書比照職業能力選項摺疊 | V3: 45998 | W3: 3.1 | X3: 。增加組織聲望(費倫派系跟艾伯倫家族都會用到對吧？)
B4: 本角卡構築在多位前人的努力上，旨在為喜愛D&D的玩家提供便利且較容易的入門手段， | M4: =ROUND((K3-M3*2.54*12)/2.54,1) -> 0 | N4: 吋 | R4: 45570 | S4: 1.3 | T4: 。載重移動到裝備與物品，並加入拖/抬/推上限 。現在開始購點出現範圍外的數字會出現error 。角色簡卡新增英雄激勵、移除速查表 | V4: 46000 | W4: 3.1.1 | X4: 。我居然現在才發現專長沒有重甲大師？？
B5: ！本角卡僅做為一個便利工具，不提供在任何形式上進行宣傳或營利手段！ | L5: 呎 | M5: =ROUND((K5*12+K6)*2.54,1) -> 0 | N5: 公分 | R5: 45576 | S5: 1.4 | T5: 。新增身高體重換算機 。移除了不存在的"變體"購點規則 。各種版面調整 | V5: 46024 | W5: 3.2 | X5: 。加入資源《銃士職業：瓦爾達的秘密尖塔》
B6: 在此感謝前人製作的角色卡 是你們給予了我啟發與動力，我玩得很開心，也才有了今天的魔改版 本角色卡翻譯僅供參考，如有歧異一切內容請以原書 D&D 2024 原文書內容為準。 P.S.隱藏工作表中有許多可供複製的內容或列表，還請多加利用 P.S.S.本角色卡並未包含2024 PHB以前的其他5e資源，請謹慎選用 P.S.S.S.本角色卡使用部分AI資源，敬請見諒 | L6: 吋 | R6: 45577 | S6: 1.4.1 | T6: 。修正了guard的譯名跟技能熟練錯誤 | V6: 46026 | W6: 3.3 | X6: 。加入資源《瓦爾達的秘密尖塔：玩家資料包》
K7: 體重換算 | R7: 45581 | S7: 1.4.2 | T7: 。修正了熾炎斬文本錯誤 。修正了負重公式錯誤的問題 | V7: 46027 | W7: 3.4a | X7: 。加入資源《鬼魅幽谷：玩家指南》職業與子職業
L8: 公斤 | M8: =ROUND(K8*2.20462262,1) -> 0 | N8: 磅 | R8: 45590 | S8: 1.4.3 | T8: 。修正了神奇的金錢紀錄bug | V8: 46028 | W8: 3.4b | X8: 。加入資源《鬼魅幽谷：玩家指南》背景&專長
R9: 45619 | S9: 1.5 | T9: 。新增堡壘頁面 | V9: 46029 | W9: 3.4c | X9: 。加入資源《鬼魅幽谷：玩家指南》法術及召喚物
L10: 磅 | M10: =ROUND(K10*0.45359237,1) -> 0 | N10: 公斤 | R10: 45627 | S10: 1.5.1 | T10: 。新增DMG自定義背景選項(這東西真的有用嗎...) | V10: 46030 | W10: 3.4d | X10: 。加入資源《鬼魅幽谷：玩家指南》種族
R11: 45637 | S11: 1.6 | T11: 。新增職業語言熟練自動化 。新增工具熟練項 。新增德魯伊：原初誓約-術師技能加值自動化 。調整魔法物品排版 。修正了裝備AC值可以跟無甲及法甲相疊的情況 。修正了造水術/枯水術的法術導航錯誤 | V11: 46031 | W11: 3.4e | X11: 。加入資源《鬼魅幽谷：玩家指南》型態轉變(在隱藏列)
R12: 45677 | S12: 1.6.1 | T12: 。修正了獸王天空野獸會是中型的問題 。修正了次元袋會記入本身重量的問題 | V12: 46032 | W12: 3.4 | X12: 。加入資源《鬼魅幽谷：玩家指南》進階武器
B13: 購點計算機 | K13: 購點表 | R13: 45726 | S13: 1.7 | T13: 。新增尋獲魔寵的部分野獸及契術師鎖鏈魔契魔寵 。新憎現代及未來武器 。又調了一次魔法物品的排版 。修正了野獸知覺、動植物定位術及舞光術的資料錯誤 | V13: 46034 | W13: 3.4.1 | X13: 。調整血量計算，整合額外生命
B14: 屬性 | C14: 屬性值 | D14: 背景加值 | E14: 專長加值 | F14: = | G14: 加總 | H14: 調整值 | I14: 花費點數 | K14: 屬性值 | M14: 花費點數 | R14: 45732 | S14: 1.7.1 | T14: 。修正了三叉戟的傷害 。修正了部分法術的錯誤 。調整部分中文翻譯 | V14: 46038 | W14: 3.4.2 | X14: 。終於想起來要補GH野蠻人原初精魂的數據了
B15: 力量 | C15: 10 | F15: = | G15: =SUM(C15:E15) -> 10 | H15: =ROUNDDOWN(G15/2,0)-5 -> 0 | I15: =IFNA(IF(OR(C15="",AND(C15<16,C15>7)),VLOOKUP(C15,$K$15:$M$22,3,FALSE),"ERROR"),"") -> 2 | K15: 8 | M15: 0 | R15: 45742 | S15: 1.7.2 | T15: 。為專長補上了英文原文 | V15: 46039 | W15: 3.5 | X15: 。加入資源《歪曲之月》 。加入資源《一發團奇觀：節慶冒險包》種族 。加入資源《火炬光下的克蘇魯》
B16: 敏捷 | C16: 12 | F16: = | G16: =SUM(C16:E16) -> 12 | H16: =ROUNDDOWN(G16/2,0)-5 -> 1 | I16: =IFNA(IF(OR(C16="",AND(C16<16,C16>7)),VLOOKUP(C16,$K$15:$M$22,3,FALSE),"ERROR"),"") -> 4 | K16: 9 | M16: 1 | R16: 45745 | S16: 1.7.3 | T16: 。種族統一改成物種了(DEI哈哈) 。修正了野蠻人3級缺少的原初知識特性 。調整部分中文翻譯 。法術列表的來源會追蹤你的物種了 | V16: 46051 | W16: 3.5.1 | X16: 。把法術DC/豁免位置替換成數值計算 。豁免列加入優劣勾選欄 。生命骰加入剩餘欄
B17: 體魄 | C17: 12 | F17: = | G17: =SUM(C17:E17) -> 12 | H17: =ROUNDDOWN(G17/2,0)-5 -> 1 | I17: =IFNA(IF(OR(C17="",AND(C17<16,C17>7)),VLOOKUP(C17,$K$15:$M$22,3,FALSE),"ERROR"),"") -> 4 | K17: 10 | M17: 2 | R17: 45753 | S17: 1.7.4 | T17: 。修正了異界坐騎的屬性值 。補上了尋獲坐騎缺少的數據 | V17: 46058 | W17: 3.6 | X17: 。加入資源《拳鬥士職業》
B18: 智力 | C18: 15 | F18: = | G18: =SUM(C18:E18) -> 15 | H18: =ROUNDDOWN(G18/2,0)-5 -> 2 | I18: =IFNA(IF(OR(C18="",AND(C18<16,C18>7)),VLOOKUP(C18,$K$15:$M$22,3,FALSE),"ERROR"),"") -> 9 | K18: 11 | M18: 3 | R18: 45754 | S18: 1.8 | T18: 。新增準備法術數量 。新增玩家手冊可購買的坐騎 | V18: 46070 | W18: 3.7 | X18: 。加入資源《探索艾伯倫》 。修復了調整豁免列所產生的一系列bug
B19: 感知 | C19: 12 | F19: = | G19: =SUM(C19:E19) -> 12 | H19: =ROUNDDOWN(G19/2,0)-5 -> 1 | I19: =IFNA(IF(OR(C19="",AND(C19<16,C19>7)),VLOOKUP(C19,$K$15:$M$22,3,FALSE),"ERROR"),"") -> 4 | K19: 12 | M19: 4 | R19: 45764 | S19: 1.8.1 | T19: 。同日dndbeyond公布第一次勘誤表，同勘誤表修改法術描述，勘誤表連結如下： https://www.dndbeyond.com/changelog#2024CoreRulesErrata | V19: 46102 | W19: 3.7.1 | X19: 。補上德魯伊缺少的施法能力 。補上奇械師子職業缺少的召喚物資料
B20: 魅力 | C20: 12 | F20: = | G20: =SUM(C20:E20) -> 12 | H20: =ROUNDDOWN(G20/2,0)-5 -> 1 | I20: =IFNA(IF(OR(C20="",AND(C20<16,C20>7)),VLOOKUP(C20,$K$15:$M$22,3,FALSE),"ERROR"),"") -> 4 | K20: 13 | M20: 5 | R20: 45788 | S20: 1.8.2 | T20: 。修正了術士7級沒有獲得術法化身能力的問題 。補上困惑術少掉的文本內容 | V20: 46133 | W20: 3.7.2 | X20: 。調整一些文本 。重新修正了德魯伊原初誓約及牧師神聖誓約的特性 。準備更新一些東西
D21: 總花費點數 | E21: =SUM(I15:I20) -> 27 | F21: / | G21: 27 | K21: 14 | M21: 7 | R21: 45794 | S21: 1.9 | T21: 。增加血脈選項自動化 。工具熟練、種族能力、專長及筆記各增加了一列 。調整部分物種及能力翻譯 。調整專長的順序 。調整生命值的排版 | V21: 46137 | W21: 3.8 | X21: 。加入資源《獅鷲的鞍袋 (一)》 。修正了遊俠子職業能力等級顯示錯誤的問題
B22: 元角色卡作者:Nicola 優化版角色卡作者:杯麵 部分修訂格式及優化來源:犬良、玉米 | H22: 角色卡作者：雷它 協作者：Klassified | K22: 15 | M22: 9 | R22: 45803 | S22: 1.10 | T22: 。法術環區重做 。裝備與物品重做 。調整角色簡卡排版 | V22: 46151 | W22: 3.9 | X22: 。新增DnD Beyond Drop 內容 (DDBD) 。加入資源《德羅林博士的恐龍寶典》物種、遊俠子職 。加回背景選項的書目(什麼時候消失的都不知道) 。調整了《艾伯倫：奇械師鍛爐》的專長位置 。修改了一些翻譯
R23: 45812 | S23: 1.10.1 | T23: 。新增牧師：神聖職責-奇術使技能加值自動化 。補上疫病射線少掉的文本內容
L24: 角色卡版本:3.9 | R24: 45815 | S24: 1.10.2 | T24: 。修正了德魯伊原初誓約及牧師神聖誓約的特性
A25: ⭣選擇書目 | R25: 45843 | S25: 1.11 | T25: 。調整了坐騎/召喚物的排版 。修正了解離術的環位 。移除了法術書的某些東西(會回來的，大概)
R26: 45859 | S26: 1.11.1 | T26: 。更新了手動的坐騎/召喚物卡 。補上了立繪的圖像比例
B27: 核心 資源 | C27: 玩家手冊(2024) | E27: PHB | H27: 合作 資源 | I27: 歪曲之月 | M27: TCM | O27: FALSE | R27: 45926 | S27: 1.11.2 | T27: 。修正了逸聞學院跟迷惑學院的文本錯誤
C28: 地下城主指南(2024) | E28: DMG | I28: 瓦爾達的秘密尖塔 | M28: VSS:PP | O28: FALSE | R28: 45961 | S28: 2.0 | T28: 。加入資源《被遺忘的國度：費倫的英雄們》 。加入書目選擇(核心資源無法取消，肯定的吧？)
C29: 怪物圖鑑(2025) | E29: MM | I29: 銃士職業：瓦爾達的秘密尖塔 | M29: GC:VSS | O29: FALSE | R29: 45970 | S29: 2.01 | T29: 。補上了一些缺漏的專長 。修改了一些翻譯
I30: 火炬光下的克蘇魯 | M30: CbT | O30: FALSE | R30: 45971 | S30: 2.1 | T30: 。將堡壘更名為據點。 。加入資源《被遺忘的國度：費倫的英雄們》據點設施。
B31: 官方 資源 | C31: 被遺忘的國度：費倫的英雄們 | E31: FPHF | F31: TRUE | I31: 鬼魅幽谷 | M31: GH | O31: FALSE | R31: 45977 | S31: 2.2 | T31: 。加入資源《阿斯代倫的飢渴之書》
C32: 洛溫：第一曙光 | E32: LFL | F32: TRUE | I32: 一發團奇觀：節慶冒險包 | M32: OSW:HAP | O32: FALSE | R32: 45980 | S32: 2.3 | T32: 。加入資源《洛溫：第一曙光》的背景與專長
C33: 阿斯代倫的飢渴之書 | E33: ABH | F33: TRUE | I33: 探索艾伯倫 | M33: EE | O33: FALSE | R33: 45987 | S33: 3.0a | T33: 。加入資源《艾伯倫：奇械師鍛爐》奇械師職業、子職業能力
C34: 艾伯倫：奇械師鍛爐 | E34: EFA | F34: TRUE | I34: 拳鬥士職業 | M34: PC | O34: FALSE | R34: 45988 | S34: 3.0b | T34: 。加入資源《艾伯倫：奇械師鍛爐》法術
I35: 獅鷲的鞍袋 (一) | M35: TGS1 | O35: FALSE | R35: 45991 | S35: 3.0c | T35: 。加入資源《艾伯倫：奇械師鍛爐》種族、背景、專長、職業能力選項 。新增角色卡生物類型欄位 。修正了兼職子職業顯示錯誤的問題
B36: DnD Beyond Drop (DDBD) | E36: 46150 | F36: FALSE | I36: 德羅林博士的恐龍寶典 (施工中) | M36: DDDD | O36: FALSE

Sheet 角色簡卡
A1: 角色簡卡
B2: 戴夫林 | J2: ='角色卡'!P7 -> 阿不 | N2: ='角色卡'!Y7 -> 人類 Human | V2: ='角色卡'!AZ7 | AA2: ='角色卡'!AY9 -> 學者 Sage | AF2: ='角色卡'!C9 -> 中型or小型 | AI2: ='角色卡'!AT9
AL3: 法術環位
B4: 角色名稱 | J4: 玩家 | N4: 物種 | V4: 所屬陣營 | AA4: 人物背景 | AF4: 體型 | AI4: 性別 | AL4: 一環 | AN4: ='法術表'!G7 -> FALSE | AO4: ='法術表'!H7 -> FALSE | AP4: ='法術表'!I7 -> FALSE | AQ4: ='法術表'!J7 -> FALSE
F6: 屬性 | I6: 豁免 | K6: ='角色卡'!V27 | L6: 血量 | P6: 先攻 | S6: 護甲值 | W6: 法術豁免\攻擊 | AC6: 法術豁免\攻擊 | AI6: 等級 | AL6: 二環 | AN6: ='法術表'!G8 -> FALSE | AO6: ='法術表'!H8 -> FALSE | AP6: ='法術表'!I8 -> FALSE
B7: 力量 | D7: ='角色卡'!G15 -> 10 | F7: ='角色卡'!J15 -> 0 | H7: ='角色卡'!P15 | I7: ='角色卡'!W15 -> 0 | L7: ='角色卡'!AA27 -> 17 | P7: ='角色卡'!AF27 -> 0 | S7: ='角色卡'!AN27 -> 12 | W7: ='角色卡'!CC33 -> 13 / +5 / +3 | AC7: ='角色卡'!CC34 | AI7: ='角色卡'!CA3 -> 3
B8: 敏捷 | D8: ='角色卡'!G16 -> 12 | F8: ='角色卡'!J16 -> 1 | H8: ='角色卡'!P16 | I8: ='角色卡'!W16 -> 1 | AL8: 三環 | AN8: ='法術表'!G9 -> FALSE | AO8: ='法術表'!H9 -> FALSE | AP8: ='法術表'!I9 -> FALSE
B9: 體魄 | D9: ='角色卡'!G17 -> 12 | F9: ='角色卡'!J17 -> 1 | H9: ='角色卡'!P17 | I9: ='角色卡'!W17 -> 1 | L9: 運動 | P9: ='角色卡'!C27 -> 0 | R9: 馴服動物 | V9: ='角色卡'!C36 -> 1 | Y9: 人設立繪
B10: 智力 | D10: ='角色卡'!G18 -> 17 | F10: ='角色卡'!J18 -> 3 | H10: ='角色卡'!P18 | I10: ='角色卡'!W18 -> 5 | L10: 特技動作 | P10: ='角色卡'!C28 -> 1 | R10: 察言觀色 | V10: ='角色卡'!C37 -> 1 | Y10: ='角色卡'!BV7 | AL10: 四環 | AN10: ='法術表'!G10 -> FALSE | AO10: ='法術表'!H10 -> FALSE | AP10: ='法術表'!I10 -> FALSE
B11: 感知 | D11: ='角色卡'!G19 -> 13 | F11: ='角色卡'!J19 -> 1 | H11: ='角色卡'!P19 | I11: ='角色卡'!W19 -> 3 | L11: 巧手 | P11: ='角色卡'!C29 -> 1 | R11: 醫藥 | V11: ='角色卡'!C38 -> 1
B12: 魅力 | D12: ='角色卡'!G20 -> 12 | F12: ='角色卡'!J20 -> 1 | H12: ='角色卡'!P20 | I12: ='角色卡'!W20 -> 1 | L12: 隱匿 | P12: ='角色卡'!C30 -> 1 | R12: 察覺 | V12: ='角色卡'!C39 -> 3 | AL12: 五環 | AN12: ='法術表'!G11 -> FALSE | AO12: ='法術表'!H11 -> FALSE | AP12: ='法術表'!I11 -> FALSE
L13: 奧秘 | P13: ='角色卡'!C31 -> 7 | R13: 求生 | V13: ='角色卡'!C40 -> 1
B14: ='角色卡'!C46 -> 13 | D14: 被動察覺 | L14: 歷史 | P14: ='角色卡'!C32 -> 5 | R14: 欺瞞 | V14: ='角色卡'!C41 -> 1 | AL14: 六環 | AN14: ='法術表'!L7 -> FALSE | AO14: ='法術表'!M7 -> FALSE
B15: ='角色卡'!C47 -> 2 | D15: 熟練加值 | L15: 調查 | P15: ='角色卡'!C33 -> 3 | R15: 威嚇 | V15: ='角色卡'!C42 -> 1
L16: 自然 | P16: ='角色卡'!C34 -> 3 | R16: 表演 | V16: ='角色卡'!C43 -> 1 | AL16: 七環 | AN16: ='法術表'!L8 -> FALSE | AO16: ='法術表'!M8 -> FALSE
B17: 職業 | L17: 宗教 | P17: ='角色卡'!C35 -> 3 | R17: 說服 | V17: ='角色卡'!C44 -> 3
A18: Ⅰ | B18: ='角色卡'!AB16 -> 法師-Wizard | G18: ='角色卡'!AK57 -> 劍詠師 | AL18: 八環 | AN18: ='法術表'!L9 -> FALSE
A19: Ⅱ | B19: ='角色卡'!AB17 | G19: ='角色卡'!BH57 | L19: 速度 | N19: 游泳 | P19: 飛行 | R19: 攀爬 | U19: 激勵
A20: Ⅲ | B20: ='角色卡'!AB18 | G20: ='角色卡'!CE57 | L20: ='角色卡'!AY18 -> 40 | N20: ='角色卡'!BB18 -> 0 | P20: ='角色卡'!AY20 -> 0 | R20: ='角色卡'!BB20 -> 0 | U20: ='角色卡'!AN30 -> FALSE | AL20: 九環 | AN20: ='法術表'!L10 -> FALSE
B21: ='裝備與物品'!AG32 -> 負重上限=150磅 現在負重=0磅 拖/抬/推上限=300磅 | AP21: ='法術表'!D12 -> 3 | AQ21: ='法術表'!D13 -> 0
AL22: 契術師環位
L23: 金幣 | P23: 銀幣 | T23: 銅幣 | AL23: ='法術表'!H13 -> 一環 | AN23: ='法術表'!J13 -> FALSE | AO23: ='法術表'!K13 -> FALSE | AP23: ='法術表'!L13 -> FALSE | AQ23: ='法術表'!M13 -> FALSE
L24: ='裝備與物品'!AG6 -> 490 | P24: ='裝備與物品'!AK6 -> 0 | T24: ='裝備與物品'!AO6 -> 0
A25: special for DM

Sheet 角色卡
CA2: 等級
CA3: =AL20 -> 3
B6: 人物設定 | BV6: 人設立繪
C7: 戴夫林 | P7: 阿不 | Y7: 人類 Human
C8: 角色名稱 | P8: 玩家名稱 | AE8: 物種 | AJ8: =IFNA(VLOOKUP(Y7,'物種'!A2:B113,2,False),"") -> PHB | AP8: 血脈 | AZ8: 所屬陣營 | BI8: 信仰神祇
C9: =Ifna(VLOOKUP(Y7,'物種'!A2:L213,3,FALSE),"") -> 中型or小型 | I9: =Ifna(VLOOKUP(Y7,'物種'!A2:L213,4,FALSE),"") -> 類人生物 | AY9: 學者 Sage
C10: 體型 | I10: 生物類型 | P10: 髮色 | U10: 膚色 | Z10: 瞳色 | AE10: 身高 | AJ10: 體重 | AO10: 年齡 | AT10: 性別 | BD10: 人物背景 | BO10: =IFNA(VLOOKUP(AY9,'背景'!A:B,2,False),"") -> PHB
B12: 主要數值
BG13: =SWITCH(AB16, "野蠻人-Barbarian", IMAGE("https://i.imgur.com/0EYltrl.png"), "法師-Wizard", IMAGE("https://i.imgur.com/B5X4tLg.png"), "術士-Sorcerer", IMAGE("https://i.imgur.com/v7SFUJL.png"), "聖騎士-Paladin", IMAGE("https://i.imgur.com/Lw78TxR.png"), "吟遊詩人-Bard", IMAGE("https://i.imgur.com/wxf5Px2.png"), "契術師-Warlock", IMAGE("https://i.imgur.com/C9HruiS.png"), "武僧-Monk", IMAGE("https://i.imgur.com/5sbMf18.png"), "牧師-Cleric", IMAGE("https://i.imgur.com/JbGHYPQ.png"), "德魯伊-Druid", IMAGE("https://i.imgur.com/Xws8X1s.png"), "遊俠-Ranger", IMAGE("https://i.imgur.com/owoN7t4.png"), "戰士-Fighter", IMAGE("https://i.imgur.com/XGIdtMF.png"), "盜賊-Rogue", IMAGE("https://imgur.com/Hvk5a27.png"), "奇械師-Artificer", IMAGE("https://i.imgur.com/BOrkMQ9.png"), "銃士-Gunslinger", IMAGE("https://duk.tw/Dq0X79.png"), "怪物獵人-Monster Hunter", IMAGE("https://duk.tw/9Zxjiv.png"), "拳鬥士-Pugilist", IMAGE("https://duk.tw/sAcpDy.jpg"), "", IMAGE("https://i.imgur.com/Ebaz1xz.png") )
C14: 屬性值 | O14: 豁免值 | AB14: 血量計算 | AY14: 經驗值
C15: 力量 | G15: 10 | J15: =ROUNDDOWN(Str/2,0)-5 -> 0 | N15: =if(O15="✓",IMAGE("https://i.imgur.com/APyehpS.png"), IF(O15="🗴",IMAGE("https://i.imgur.com/wXw7xUR.png"),"")) | Q15: FALSE | S15: 力量 | W15: =StrMod+IF('角色卡'!Q15=TRUE,Prof,0) -> 0 | AB15: 職業 | AL15: Lv | AN15: 生命骰 | AS15: HP | AU15: 體魄 | AY15: 0
C16: 敏捷 | G16: 12 | J16: =ROUNDDOWN(Dex/2,0)-5 -> 1 | N16: =if(O16="✓",IMAGE("https://i.imgur.com/APyehpS.png"), IF(O16="🗴",IMAGE("https://i.imgur.com/wXw7xUR.png"),"")) | Q16: FALSE | S16: 敏捷 | W16: =DexMod+IF('角色卡'!Q16=TRUE,Prof,0) -> 1 | Z16: Ⅰ | AB16: 法師-Wizard | AL16: 3 | AN16: =SWITCH(AB16, "野蠻人-Barbarian", "1d12", "法師-Wizard", "1d6", "術士-Sorcerer", "1d6", "聖騎士-Paladin", "1d10", "吟遊詩人-Bard", "1d8", "契術師-Warlock", "1d8", "武僧-Monk", "1d8", "牧師-Cleric", "1d8", "德魯伊-Druid", "1d8", "遊俠-Ranger", "1d10", "戰士-Fighter", "1d10", "盜賊-Rogue", "1d8", "奇械師-Artificer", "1d8", "銃士-Gunslinger", "1d8", "怪物獵人-Monster Hunter", "1d10", "拳鬥士-Pugilist", "1d10", "", "") -> 1d6 | AU16: =IF(AL16="","",AL16*ConMod) -> 3
C17: 體魄 | G17: 12 | J17: =ROUNDDOWN(Con/2,0)-5 -> 1 | N17: =if(O17="✓",IMAGE("https://i.imgur.com/APyehpS.png"), IF(O17="🗴",IMAGE("https://i.imgur.com/wXw7xUR.png"),"")) | S17: 體魄 | W17: =ConMod+IF('角色卡'!Q17=TRUE,Prof,0) -> 1 | Z17: Ⅱ | AN17: =SWITCH(AB17, "野蠻人-Barbarian", "1d12", "法師-Wizard", "1d6", "術士-Sorcerer", "1d6", "聖騎士-Paladin", "1d10", "吟遊詩人-Bard", "1d8", "契術師-Warlock", "1d8", "武僧-Monk", "1d8", "牧師-Cleric", "1d8", "德魯伊-Druid", "1d8", "遊俠-Ranger", "1d10", "戰士-Fighter", "1d10", "盜賊-Rogue", "1d8", "奇械師-Artificer", "1d8", "銃士-Gunslinger", "1d8", "怪物獵人-Monster Hunter", "1d10", "", "") | AU17: =IF(AL17="","",AL17*ConMod) | AY17: 速度 | BB17: 游泳
C18: 智力 | G18: 17 | J18: =ROUNDDOWN(Int/2,0)-5 -> 3 | N18: =if(O18="✓",IMAGE("https://i.imgur.com/APyehpS.png"), IF(O18="🗴",IMAGE("https://i.imgur.com/wXw7xUR.png"),"")) | Q18: TRUE | S18: 智力 | W18: =IntMod+IF('角色卡'!Q18=TRUE,Prof,0) -> 5 | Z18: Ⅲ | AN18: =SWITCH(AB18, "野蠻人-Barbarian", "1d12", "法師-Wizard", "1d6", "術士-Sorcerer", "1d6", "聖騎士-Paladin", "1d10", "吟遊詩人-Bard", "1d8", "契術師-Warlock", "1d8", "武僧-Monk", "1d8", "牧師-Cleric", "1d8", "德魯伊-Druid", "1d8", "遊俠-Ranger", "1d10", "戰士-Fighter", "1d10", "盜賊-Rogue", "1d8", "奇械師-Artificer", "1d8", "銃士-Gunslinger", "1d8", "怪物獵人-Monster Hunter", "1d10", "", "") | AU18: =IF(AL18="","",AL18*ConMod) | AY18: 40 | BB18: 0
C19: 感知 | G19: 13 | J19: =ROUNDDOWN(Wis/2,0)-5 -> 1 | N19: =if(O19="✓",IMAGE("https://i.imgur.com/APyehpS.png"), IF(O19="🗴",IMAGE("https://i.imgur.com/wXw7xUR.png"),"")) | Q19: TRUE | S19: 感知 | W19: =WisMod+IF('角色卡'!Q19=TRUE,Prof,0) -> 3 | AF19: 每級額外生命 | AN19: 總額外生命 | AU19: =AL20*AL19 -> 0 | AY19: 飛行 | BB19: 攀爬
C20: 魅力 | G20: 12 | J20: =ROUNDDOWN(Cha/2,0)-5 -> 1 | N20: =if(O20="✓",IMAGE("https://i.imgur.com/APyehpS.png"), IF(O20="🗴",IMAGE("https://i.imgur.com/wXw7xUR.png"),"")) | Q20: FALSE | S20: 魅力 | W20: =ChaMod+IF('角色卡'!Q20=TRUE,Prof,0) -> 1 | AB20: 總等級 | AL20: =SUM(AL16:AM18) -> 3 | AN20: ᚲᚢᛈᚾᛟᛟᛞᛚᛖ9141 | AS20: =SUM(AS16:AT18) -> 0 | AU20: =SUM(AU16:AV18) -> 3 | AY20: 0 | BB20: 0
J21: 調整值 | O21: 優劣 | Q21: 熟練 | W21: 調整值
R22: Icon | U22: FALSE | AC22: =SUM(AF22:AJ22) -> 9 | AE22: = | AF22: =MAX(AL20-1,0) -> 2 | AH22: + | AI22: =AL22 -> 7 | AK22: = | AL22: =IF(OR(AN16="1d6"),6+ConMod,IF(OR(AN16="1d8"),8+ConMod,IF(OR(AN16="1d10"),10+ConMod,IF(OR(AN16="1d12"),12+ConMod,0)))) -> 7 | AT22: =MAX(SUM(AS20:AV20),0) -> 3 | AW22: =IF(and(AT22=0,abs(AS20)>=AU20),1,0) -> 0
X23: .
B24: 技能數值 | V24: 戰鬥數值
X25: 臨時生命 | AB25: 0 | AF25: 警覺 | AJ25: FALSE
C26: 加值 | F26: 技能 | N26: 熟練 | Q26: 優劣 | X26: 生命值 | AF26: 先攻加值 | AN26: 護甲值 | AV26: 護甲 | AY26: 智力 | BB26: 法師 | BF26: 箭袋/弩矢匣 | BP26: 穿戴護甲 | BX26: 屬性 | CA26: AC | CD26: 敏捷 | CG26: 劣勢 | CJ26: 重量
B27: =if(Q27="✓",IMAGE("https://i.imgur.com/APyehpS.png"), IF(Q27="🗴",IMAGE("https://i.imgur.com/wXw7xUR.png"),"")) | C27: =StrMod+(Prof*IF(N27="x2",2,IF(N27="½",0.4,IF(N27="●",1,0)))) -> 0 | F27: 運動-力量 | V27: =IF(U22=true,IMAGE("https://i.imgur.com/Ko3ATxC.png"),"") | X27: 17 | AA27: 17 | AF27: 0 | AI27: =J16+IF(OR(AK57="幽域追蹤者",BH57="幽域追蹤者",CE57="幽域追蹤者"),J19)+IF(AJ25=TRUE,C47) -> 1 | AL27: =IF(U22=true,IMAGE("https://i.imgur.com/SB2v8hd.png"),"") | AN27: 12 | AT27: = | AV27: =CA27 -> 10 | AY27: =2 -> 2 | BB27: =IF(AND(BX27="法師",BR27=""),IF(3-AV29<0,0,3-AV29),"") | BF27: 0 | BI27: 無 | CA27: =IFNA(VLOOKUP(BR27,'武器&護甲'!J2:L14,2,FALSE),10)+BP27 -> 10 | CD27: =IF(BX27="重甲",0,IF(BX27="中甲",IF(DexMod>=2,2,DexMod),DexMod)) -> 1 | CG27: FALSE | CJ27: =IFNA(VLOOKUP(BR27,'武器&護甲'!J2:L14,3,FALSE),0) -> 0
B28: =if(Q28="✓",IMAGE("https://i.imgur.com/APyehpS.png"), IF(Q28="🗴",IMAGE("https://i.imgur.com/wXw7xUR.png"),"")) | C28: =DexMod+(Prof*IF(N28="x2",2,IF(N28="½",0.4,IF(N28="●",1,0)))) -> 1 | F28: 特技動作-敏捷 | Q28: ✓ | AV28: 無甲 | AY28: 天生 | BB28: 其他 | BF28: 0 | BI28: 無 | BR28: 盾牌 | CA28: =IF(BX28="卸下",0,IF(BX28="握持",2+BP28,IF(BX28="無",0,))) | CD28: 它 | CG28: FALSE | CJ28: =IF(BX28="卸下",6,IF(BX28="握持",6,IF(BX28="無",0,)))
B29: =if(Q29="✓",IMAGE("https://i.imgur.com/APyehpS.png"), IF(Q29="🗴",IMAGE("https://i.imgur.com/wXw7xUR.png"),"")) | C29: =DexMod+(Prof*IF(N29="x2",2,IF(N29="½",0.4,IF(N29="●",1,0)))) -> 1 | F29: 巧手-敏捷 | X29: 目前 | AA29: 最大 | AF29: 目前 | AI29: 加值 | BF29: 0 | BI29: 無 | BX29: 合計: | CA29: =SUM(CA27:CC28)+CD27 -> 11
B30: =if(Q30="✓",IMAGE("https://i.imgur.com/APyehpS.png"), IF(Q30="🗴",IMAGE("https://i.imgur.com/wXw7xUR.png"),"")) | C30: =DexMod+(Prof*IF(N30="x2",2,IF(N30="½",0.4,IF(N30="●",1,0)))) -> 1 | F30: 隱匿-敏捷 | X30: 生命骰 | AH30: 英雄激勵 | AN30: FALSE
B31: =if(Q31="✓",IMAGE("https://i.imgur.com/APyehpS.png"), IF(Q31="🗴",IMAGE("https://i.imgur.com/wXw7xUR.png"),"")) | C31: =IntMod+(Prof*IF(N31="x2",2,IF(N31="½",0.4,IF(N31="●",1,0))))+IF(AND('職業能力選項'!R3="-魔術師",'職業能力'!E2>0),IF(WisMod>1,WisMod,1),"")+IF(AND('職業能力選項'!N3="-奇術使",'職業能力'!D2>0),IF(WisMod>1,WisMod,1),"") -> 7 | F31: 奧秘-智力 | N31: x2 | V31: D6 | Z31: =SUMIF(AN16:AR18, "1d6", AL16:AM18) -> 3 | AB31: =IF(Z31>0,if(ConMod<0,"1d6"&ConMod,if(ConMod=0,"1d6"&"+"&+0,"1d6"&"+"&+ConMod)),"") -> 1d6+1 | AU31: 術法點 | BB31: 狂暴 | BI31: 功力 | BP31: 武藝 | BW31: 數值計算
B32: =if(Q32="✓",IMAGE("https://i.imgur.com/APyehpS.png"), IF(Q32="🗴",IMAGE("https://i.imgur.com/wXw7xUR.png"),"")) | C32: =IntMod+(Prof*IF(N32="x2",2,IF(N32="½",0.4,IF(N32="●",1,0)))) -> 5 | F32: 歷史-智力 | N32: ● | V32: D8 | Z32: =SUMIF(AN16:AR18, "1d8", AL16:AM18) -> 0 | AB32: =IF(Z32>0,if(ConMod<0,"1d8"&ConMod,if(ConMod=0,"1d8"&"+"&+0,"1d8"&"+"&+ConMod)),"") | AH32: ~死亡豁免~ | BW32: 屬性 | BZ32: 額外 | CC32: DC / 檢定 / 加值
B33: =if(Q33="✓",IMAGE("https://i.imgur.com/APyehpS.png"), IF(Q33="🗴",IMAGE("https://i.imgur.com/wXw7xUR.png"),"")) | C33: =IntMod+(Prof*IF(N33="x2",2,IF(N33="½",0.4,IF(N33="●",1,0)))) -> 3 | F33: 調查-智力 | V33: D10 | Z33: =SUMIF(AN16:AR18, "1d10", AL16:AM18) -> 0 | AB33: =IF(Z33>0,if(ConMod<0,"1d10"&ConMod,if(ConMod=0,"1d10"&"+"&+0,"1d10"&"+"&+ConMod)),"") | AH33: 成功( ≧10) | AM33: FALSE | AO33: FALSE | AQ33: FALSE | BW33: 智力 | CC33: =IF(BW33="","",'索引資料'!J33&" / "&TEXT('索引資料'!K33,'索引資料'!K33)&" / "&TEXT('索引資料'!L33,'索引資料'!L33)) -> 13 / +5 / +3
B34: =if(Q34="✓",IMAGE("https://i.imgur.com/APyehpS.png"), IF(Q34="🗴",IMAGE("https://i.imgur.com/wXw7xUR.png"),"")) | C34: =IntMod+(Prof*IF(N34="x2",2,IF(N34="½",0.4,IF(N34="●",1,0))))+IF(AND('職業能力選項'!R3="-魔術師",'職業能力'!E2>0),IF(WisMod>1,WisMod,1),"") -> 3 | F34: 自然-智力 | V34: D12 | Z34: =SUMIF(AN16:AR18, "1d12", AL16:AM18) -> 0 | AB34: =IF(Z34>0,if(ConMod<0,"1d12"&ConMod,if(ConMod=0,"1d12"&"+"&+0,"1d12"&"+"&+ConMod)),"") | AH34: 失敗(＜10) | AM34: FALSE | AO34: FALSE | AQ34: FALSE | AU34: 剩餘次數 | AY34: - | BB34: 剩餘次數 | BF34: - | BI34: 剩餘次數 | BM34: - | BP34: 剩餘次數 | BT34: - | CC34: =IF(BW34="","",'索引資料'!J34&" / "&TEXT('索引資料'!K34,'索引資料'!K34)&" / "&TEXT('索引資料'!L34,'索引資料'!L34))
B35: =if(Q35="✓",IMAGE("https://i.imgur.com/APyehpS.png"), IF(Q35="🗴",IMAGE("https://i.imgur.com/wXw7xUR.png"),"")) | C35: =IntMod+(Prof*IF(N35="x2",2,IF(N35="½",0.4,IF(N35="●",1,0))))+IF(AND('職業能力選項'!N3="-奇術使",'職業能力'!D2>0),IF(WisMod>1,WisMod,1),"") -> 3 | F35: 宗教-智力 | X35: 剩餘 | Z35: 最大 | CC35: =IF(BW35="","",'索引資料'!J35&" / "&TEXT('索引資料'!K35,'索引資料'!K35)&" / "&TEXT('索引資料'!L35,'索引資料'!L35))
B36: =if(Q36="✓",IMAGE("https://i.imgur.com/APyehpS.png"), IF(Q36="🗴",IMAGE("https://i.imgur.com/wXw7xUR.png"),"")) | C36: =WisMod+(Prof*IF(N36="x2",2,IF(N36="½",0.4,IF(N36="●",1,0)))) -> 1 | F36: 動物馴服-感知 | X36: 武器與法器 | AF36: 命中 | AI36: 傷害骰 | AO36: 調整值 | AR36: 距離 | AV36: 傷害 | AY36: 重量 | BB36: # | BD36: 精 | BF36: 精通屬性 | BL36: 屬性
B37: =if(Q37="✓",IMAGE("https://i.imgur.com/APyehpS.png"), IF(Q37="🗴",IMAGE("https://i.imgur.com/wXw7xUR.png"),"")) | C37: =WisMod+(Prof*IF(N37="x2",2,IF(N37="½",0.4,IF(N37="●",1,0)))) -> 1 | F37: 察言觀色-感知 | Z37: 長劍 | AF37: =2 -> 2 | AI37: =IFNA((VLOOKUP(Z37,'武器&護甲'!$A$2:$H$118,3,False))&X37,"") -> 1d8(1d10) | AO37: 0 | AR37: =IFNA(VLOOKUP(Z37,'武器&護甲'!$A$2:$H$118,4,False),"") -> 觸及 | AV37: =IFNA(VLOOKUP(Z37,'武器&護甲'!$A$2:$H$118,5,False),"") -> 劈砍 | AY37: =IFNA(VLOOKUP(Z37,'武器&護甲'!$A$2:$H$118,6,FALSE),"") -> 3 | BD37: FALSE | BF37: =IFNA(IF(BD37=TRUE,VLOOKUP(Z37,'武器&護甲'!$A$2:$H$118,8,False),""),"") | BL37: =IFNA(VLOOKUP(Z37,'武器&護甲'!$A$2:$H$118,7,False),"") -> 可雙手 | BW37: 筆記
B38: =if(Q38="✓",IMAGE("https://i.imgur.com/APyehpS.png"), IF(Q38="🗴",IMAGE("https://i.imgur.com/wXw7xUR.png"),"")) | C38: =WisMod+(Prof*IF(N38="x2",2,IF(N38="½",0.4,IF(N38="●",1,0)))) -> 1 | F38: 醫藥-感知 | AI38: =IFNA((VLOOKUP(Z38,'武器&護甲'!$A$2:$H$118,3,False))&X38,"") | AR38: =IFNA(VLOOKUP(Z38,'武器&護甲'!$A$2:$H$118,4,False),"") | AV38: =IFNA(VLOOKUP(Z38,'武器&護甲'!$A$2:$H$118,5,False),"") | AY38: =IFNA(VLOOKUP(Z38,'武器&護甲'!$A$2:$H$118,6,FALSE),"") | BD38: FALSE | BF38: =IFNA(IF(BD38=TRUE,VLOOKUP(Z38,'武器&護甲'!$A$2:$H$118,8,False),""),"") | BL38: =IFNA(VLOOKUP(Z38,'武器&護甲'!$A$2:$H$118,7,False),"") | BW38: 攻擊擲骰(+2)
B39: =if(Q39="✓",IMAGE("https://i.imgur.com/APyehpS.png"), IF(Q39="🗴",IMAGE("https://i.imgur.com/wXw7xUR.png"),"")) | C39: =WisMod+(Prof*IF(N39="x2",2,IF(N39="½",0.4,IF(N39="●",1,0)))) -> 3 | F39: 察覺-感知 | N39: ● | AI39: =IFNA((VLOOKUP(Z39,'武器&護甲'!$A$2:$H$118,3,False))&X39,"") | AR39: =IFNA(VLOOKUP(Z39,'武器&護甲'!$A$2:$H$118,4,False),"") | AV39: =IFNA(VLOOKUP(Z39,'武器&護甲'!$A$2:$H$118,5,False),"") | AY39: =IFNA(VLOOKUP(Z39,'武器&護甲'!$A$2:$H$118,6,FALSE),"") | BD39: FALSE | BF39: =IFNA(IF(BD39=TRUE,VLOOKUP(Z39,'武器&護甲'!$A$2:$H$118,8,False),""),"") | BL39: =IFNA(VLOOKUP(Z39,'武器&護甲'!$A$2:$H$118,7,False),"") | BW39: 可以花費其中的一次使用次數，並使用一個動作治療你 5 呎內的一個生物。該生物花費一個自身的生命骰，然後你擲出該骰。該生物恢復的生命值等於擲出的結果加上你的熟練加值。
B40: =if(Q40="✓",IMAGE("https://i.imgur.com/APyehpS.png"), IF(Q40="🗴",IMAGE("https://i.imgur.com/wXw7xUR.png"),"")) | C40: =WisMod+(Prof*IF(N40="x2",2,IF(N40="½",0.4,IF(N40="●",1,0)))) -> 1 | F40: 求生-感知 | AI40: =IFNA((VLOOKUP(Z40,'武器&護甲'!$A$2:$H$118,3,False))&X40,"") | AR40: =IFNA(VLOOKUP(Z40,'武器&護甲'!$A$2:$H$118,4,False),"") | AV40: =IFNA(VLOOKUP(Z40,'武器&護甲'!$A$2:$H$118,5,False),"") | AY40: =IFNA(VLOOKUP(Z40,'武器&護甲'!$A$2:$H$118,6,FALSE),"") | BD40: FALSE | BF40: =IFNA(IF(BD40=TRUE,VLOOKUP(Z40,'武器&護甲'!$A$2:$H$118,8,False),""),"") | BL40: =IFNA(VLOOKUP(Z40,'武器&護甲'!$A$2:$H$118,7,False),"")
B41: =if(Q41="✓",IMAGE("https://i.imgur.com/APyehpS.png"), IF(Q41="🗴",IMAGE("https://i.imgur.com/wXw7xUR.png"),"")) | C41: =ChaMod+(Prof*IF(N41="x2",2,IF(N41="½",0.4,IF(N41="●",1,0)))) -> 1 | F41: 欺瞞-魅力 | AI41: =IFNA((VLOOKUP(Z41,'武器&護甲'!$A$2:$H$118,3,False))&X41,"") | AR41: =IFNA(VLOOKUP(Z41,'武器&護甲'!$A$2:$H$118,4,False),"") | AV41: =IFNA(VLOOKUP(Z41,'武器&護甲'!$A$2:$H$118,5,False),"") | AY41: =IFNA(VLOOKUP(Z41,'武器&護甲'!$A$2:$H$118,6,FALSE),"") | BD41: FALSE | BF41: =IFNA(IF(BD41=TRUE,VLOOKUP(Z41,'武器&護甲'!$A$2:$H$118,8,False),""),"") | BL41: =IFNA(VLOOKUP(Z41,'武器&護甲'!$A$2:$H$118,7,False),"")
B42: =if(Q42="✓",IMAGE("https://i.imgur.com/APyehpS.png"), IF(Q42="🗴",IMAGE("https://i.imgur.com/wXw7xUR.png"),"")) | C42: =ChaMod+(Prof*IF(N42="x2",2,IF(N42="½",0.4,IF(N42="●",1,0)))) -> 1 | F42: 威嚇-魅力 | AI42: =IFNA((VLOOKUP(Z42,'武器&護甲'!$A$2:$H$118,3,False))&X42,"") | AR42: =IFNA(VLOOKUP(Z42,'武器&護甲'!$A$2:$H$118,4,False),"") | AV42: =IFNA(VLOOKUP(Z42,'武器&護甲'!$A$2:$H$118,5,False),"") | AY42: =IFNA(VLOOKUP(Z42,'武器&護甲'!$A$2:$H$118,6,FALSE),"") | BD42: FALSE | BF42: =IFNA(IF(BD42=TRUE,VLOOKUP(Z42,'武器&護甲'!$A$2:$H$118,8,False),""),"") | BL42: =IFNA(VLOOKUP(Z42,'武器&護甲'!$A$2:$H$118,7,False),"")
B43: =if(Q43="✓",IMAGE("https://i.imgur.com/APyehpS.png"), IF(Q43="🗴",IMAGE("https://i.imgur.com/wXw7xUR.png"),"")) | C43: =ChaMod+(Prof*IF(N43="x2",2,IF(N43="½",0.4,IF(N43="●",1,0)))) -> 1 | F43: 表演-魅力
B44: =if(Q44="✓",IMAGE("https://i.imgur.com/APyehpS.png"), IF(Q44="🗴",IMAGE("https://i.imgur.com/wXw7xUR.png"),"")) | C44: =ChaMod+(Prof*IF(N44="x2",2,IF(N44="½",0.4,IF(N44="●",1,0)))) -> 3 | F44: 說服-魅力 | N44: ● | X44: 物種能力 | AV44: 專長
...

Sheet 職業能力選項
A1: 野蠻人 | H1: 吟遊詩人 | L1: 牧師 | P1: 德魯伊 | W1: 戰士 | AD1: 武僧 | AH1: 聖騎士 | AM1: 遊俠 | AT1: 盜賊 | AY1: 術士 | BC1: 契術師 | BG1: 法師 | BK1: =IF('請先閱讀'!$F$34=true,"奇械師","") -> 奇械師 | BO1: =IF('請先閱讀'!$O$29=true,"銃士","") | BT1: =IF('請先閱讀'!$O$31=true,"怪物獵人","")
C2: 武器精通 | D2: 精通屬性 | F2: 荒野之心形貌 | J2: =IF('請先閱讀'!$O$31=true,"冒險者學院天賦","") | N2: 神聖誓約 | R2: 原初誓約 | T2: 大地結社法術 | U2: 傷害類型 | Y2: 武器精通 | Z2: 精通屬性 | AB2: 戰鬥大師戰技 | AF2: 活體武器顯化 | AJ2: 武器精通 | AK2: 精通屬性 | AO2: 武器精通 | AP2: 精通屬性 | AR2: 原初動物夥伴 | AV2: 武器精通 | AW2: 精通屬性 | BA2: 超魔法 | BE2: 魔能祈喚 | BI2: 預言學派天眼通 | BM2: 魔法物品方案 | BQ2: 武器精通 | BR2: 精通屬性 | BV2: 怪物寶典
D3: =IFNA(VLOOKUP(C3,'武器&護甲'!$A$2:$H$58,8,FALSE),"") | F3: (請選擇) | N3: (請選擇) | R3: (請選擇) | T3: (請選擇) | Z3: =IFNA(VLOOKUP(Y3,'武器&護甲'!$A$2:$H$58,8,FALSE),"") | AF3: (請選擇) | AK3: =IFNA(VLOOKUP(AJ3,'武器&護甲'!$A$2:$H$58,8,FALSE),"") | AP3: =IFNA(VLOOKUP(AO3,'武器&護甲'!$A$2:$H$58,8,FALSE),"") | AW3: =IFNA(VLOOKUP(AV3,'武器&護甲'!$A$2:$H$58,8,FALSE),"") | BI3: (請選擇) | BR3: =IFNA(VLOOKUP(BQ3,'武器&護甲'!$A$2:$H$58,8,FALSE),"")
D4: =IFNA(VLOOKUP(C4,'武器&護甲'!$A$2:$H$58,8,FALSE),"") | Z4: =IFNA(VLOOKUP(Y4,'武器&護甲'!$A$2:$H$58,8,FALSE),"") | AK4: =IFNA(VLOOKUP(AJ4,'武器&護甲'!$A$2:$H$58,8,FALSE),"") | AP4: =IFNA(VLOOKUP(AO4,'武器&護甲'!$A$2:$H$58,8,FALSE),"") | AW4: =IFNA(VLOOKUP(AV4,'武器&護甲'!$A$2:$H$58,8,FALSE),"") | BR4: =IFNA(VLOOKUP(BQ4,'武器&護甲'!$A$2:$H$58,8,FALSE),"")
D5: =IFNA(VLOOKUP(C5,'武器&護甲'!$A$2:$H$58,8,FALSE),"") | F5: =IF('請先閱讀'!$O$31=true,"憤怒亡靈宣洩","") | N5: 受祝擊 | R5: 已知型態 | T5: 星辰宇宙預兆 | Z5: =IFNA(VLOOKUP(Y5,'武器&護甲'!$A$2:$H$58,8,FALSE),"") | AR5: 獵人狩者獵物 | BI5: =IF('請先閱讀'!$O$31=true,"惡魔學家善惡","") | BR5: =IFNA(VLOOKUP(BQ5,'武器&護甲'!$A$2:$H$58,8,FALSE),"")
D6: =IFNA(VLOOKUP(C6,'武器&護甲'!$A$2:$H$58,8,FALSE),"") | F6: (請選擇) | N6: (請選擇) | T6: (請選擇) | Z6: =IFNA(VLOOKUP(Y6,'武器&護甲'!$A$2:$H$58,8,FALSE),"") | AV6: =IF('請先閱讀'!$O$31=true,"厄運使者禍術","") | BI6: (請選擇) | BR6: =IFNA(VLOOKUP(BQ6,'武器&護甲'!$A$2:$H$58,8,FALSE),"")
Z7: =IFNA(VLOOKUP(Y7,'武器&護甲'!$A$2:$H$58,8,FALSE),"")
T8: =IF('請先閱讀'!$O$31=true,"熵力結社災難","") | Z8: =IFNA(VLOOKUP(Y8,'武器&護甲'!$A$2:$H$58,8,FALSE),"") | AR8: 獵人防守戰術 | BQ8: 銃士戰技 | BV8: 武器精通 | BW8: 精通屬性
T9: (請選擇) | BW9: =IFNA(VLOOKUP(BV9,'武器&護甲'!$A$2:$H$58,8,FALSE),"")
Y10: =IF('請先閱讀'!$O$31=true,"活體坩堝化合物","") | BA10: =IF('請先閱讀'!$O$31=true,"悲慘血脈詛咒","") | BW10: =IFNA(VLOOKUP(BV10,'武器&護甲'!$A$2:$H$58,8,FALSE),"")
BA11: (請選擇) | BW11: =IFNA(VLOOKUP(BV11,'武器&護甲'!$A$2:$H$58,8,FALSE),"")
BW12: =IFNA(VLOOKUP(BV12,'武器&護甲'!$A$2:$H$58,8,FALSE),"")
BW13: =IFNA(VLOOKUP(BV13,'武器&護甲'!$A$2:$H$58,8,FALSE),"")
BE14: =IF('請先閱讀'!$O$31=true,"宇宙寄生體肉體","")
R15: =IF(R$2>=7,"元素狂怒","") -> 元素狂怒
R16: (請選擇)

Sheet 索引資料
B2: 施法等級 | E2: 法術來源 | G2: 職業技能熟練 | K2: 子職業列表
B3: 術 | C3: ='職業能力'!N2 -> 0 | E3: =IF('角色卡'!Y7="","物種",K38) -> 人類 | G3: 野蠻人-Barbarian | H3: 選擇2項：動物馴服、運動、威嚇、自然、察覺、求生 | K3: 野蠻人-Barbarian | L3: 狂戰士道途 | M3: 荒野之心道途 | N3: 世界樹道途 | O3: 狂熱者道途 | P3: =IF('請先閱讀'!$O$27=true,"實驗道途","") | Q3: =IF('請先閱讀'!O28=true,"肌肉魔法使道途","") | R3: =IF('請先閱讀'!$O$30=true,"蔑法道途","") | S3: =IF('請先閱讀'!$O$31=true,"分裂道途","") | T3: =IF('請先閱讀'!$O$31=true,"原初精魂道途","") | U3: =IF('請先閱讀'!$O$31=true,"憤怒亡靈道途","") | V3: =IF('請先閱讀'!O35=true,"冰川道途","")
B4: 法 | C4: ='職業能力'!P2 -> 3 | E4: =IF('角色卡'!AB16="野蠻人-Barbarian","野蠻人",IF('角色卡'!AB16="法師-Wizard","法師",IF('角色卡'!AB16="術士-Sorcerer","術士",IF('角色卡'!AB16="聖騎士-Paladin","聖騎士",IF('角色卡'!AB16="武僧-Monk","武僧",IF('角色卡'!AB16="契術師-Warlock","契術師",IF('角色卡'!AB16="吟遊詩人-Bard","吟遊詩人",IF('角色卡'!AB16="牧師-Cleric","牧師",IF('角色卡'!AB16="德魯伊-Druid","德魯伊",IF('角色卡'!AB16="遊俠-Ranger","遊俠",IF('角色卡'!AB16="戰士-Fighter","戰士",IF('角色卡'!AB16="盜賊-Rogue","盜賊",IF('角色卡'!AB16="奇械師-Artificer","奇械師","職業"))))))))))))) -> 法師 | G4: 吟遊詩人-Bard | H4: 任選3個技能 | K4: 吟遊詩人-Bard | L4: 舞蹈學院 | M4: 迷惑學院 | N4: 軼聞學院 | O4: 勇氣學院 | P4: =IF('請先閱讀'!F31=true,"月亮學院","") -> 月亮學院 | Q4: =IF('請先閱讀'!$O$27=true,"靈哨學院","") | R4: =IF('請先閱讀'!$O$30=true,"戲劇學院","") | S4: =IF('請先閱讀'!$O$31=true,"冒險者學院","") | T4: =IF('請先閱讀'!$O$31=true,"弄臣學院","") | U4: =IF('請先閱讀'!$O$31=true,"安魂學院","") | V4: =IF('請先閱讀'!$O$33=true,"傳頌學院","") | W4: =IF('請先閱讀'!O35=true,"織舞學院","")
B5: 牧 | C5: ='職業能力'!D2 -> 0 | E5: ='角色卡'!AK57 -> 劍詠師 | G5: 牧師-Cleric | H5: 選擇2項：歷史、察言觀色、醫藥、說服、宗教 | K5: 牧師-Cleric | L5: 生命領域 | M5: 光明領域 | N5: 詭術領域 | O5: 戰爭領域 | P5: =IF('請先閱讀'!F31=true,"知識領域","") -> 知識領域 | Q5: =IF('請先閱讀'!$O$27=true,"豐收領域","") | R5: =IF('請先閱讀'!$O$30=true,"天啟領域","") | S5: =IF('請先閱讀'!$O$31=true,"怪異領域","") | T5: =IF('請先閱讀'!$O$31=true,"審判領域","") | U5: =IF('請先閱讀'!$O$31=true,"淨化領域","") | V5: =IF('請先閱讀'!$O$33=true,"心靈領域","") | W5: =IF('請先閱讀'!O35=true,"星界領域","")
B6: 吟 | C6: ='職業能力'!C2 -> 0 | E6: =IF('角色卡'!AB17="野蠻人-Barbarian","野蠻人",IF('角色卡'!AB17="法師-Wizard","法師",IF('角色卡'!AB17="術士-Sorcerer","術士",IF('角色卡'!AB17="聖騎士-Paladin","聖騎士",IF('角色卡'!AB17="武僧-Monk","武僧",IF('角色卡'!AB17="契術師-Warlock","契術師",IF('角色卡'!AB17="吟遊詩人-Bard","吟遊詩人",IF('角色卡'!AB17="牧師-Cleric","牧師",IF('角色卡'!AB17="德魯伊-Druid","德魯伊",IF('角色卡'!AB17="遊俠-Ranger","遊俠",IF('角色卡'!AB17="戰士-Fighter","戰士",IF('角色卡'!AB17="盜賊-Rogue","盜賊",IF('角色卡'!AB17="奇械師-Artificer","奇械師",""))))))))))))) | G6: 德魯伊-Druid | H6: 選擇2項：奧秘、動物馴服、察言觀色、醫藥、自然、察覺、宗教、求生 | K6: 德魯伊-Druid | L6: 大地結社 | M6: 月亮結社 | N6: 海洋結社 | O6: 星辰結社 | P6: =IF('請先閱讀'!$O$27=true,"古道結社","") | Q6: =IF('請先閱讀'!$O$27=true,"柳條結社","") | R6: =IF('請先閱讀'!$O$30=true,"共生結社","") | S6: =IF('請先閱讀'!$O$31=true,"鮮血結社","") | T6: =IF('請先閱讀'!$O$31=true,"熵力結社","") | U6: =IF('請先閱讀'!$O$31=true,"突變結社","") | V6: =IF('請先閱讀'!$O$33=true,"鍛物結社","") | W6: =IF('請先閱讀'!O35=true,"不朽結社","") | X6: =IF('請先閱讀'!O36=true,"輪轉結社","")
B7: 德 | C7: ='職業能力'!E2 -> 0 | E7: ='角色卡'!BH57 | G7: 戰士-Fighter | H7: 選擇2項：特技、動物馴服、運動、歷史、察言觀色、威嚇、說服、察覺、求生 | K7: 戰士-Fighter | L7: 戰鬥大師 | M7: 勇士 | N7: 魔能騎士 | O7: 靈能武士 | P7: =IF('請先閱讀'!F31=true,"旗將","") -> 旗將 | Q7: =IF('請先閱讀'!$O$27=true,"陵墓守衛","") | R7: =IF('請先閱讀'!O28=true,"地城探險家","") | S7: =IF('請先閱讀'!$O$30=true,"英雄","") | T7: =IF('請先閱讀'!$O$31=true,"壁壘衛士","") | U7: =IF('請先閱讀'!$O$31=true,"活體坩堝","") | V7: =IF('請先閱讀'!$O$31=true,"守夜人","") | W7: =IF('請先閱讀'!O35=true,"羽蛇傳令","") | X7: =IF('請先閱讀'!O36=true,"雕骨師","")
B8: 遊 | C8: ='職業能力'!L2 -> 0 | E8: =IF('角色卡'!AB18="野蠻人-Barbarian","野蠻人",IF('角色卡'!AB18="法師-Wizard","法師",IF('角色卡'!AB18="術士-Sorcerer","術士",IF('角色卡'!AB18="聖騎士-Paladin","聖騎士",IF('角色卡'!AB18="武僧-Monk","武僧",IF('角色卡'!AB18="契術師-Warlock","契術師",IF('角色卡'!AB18="吟遊詩人-Bard","吟遊詩人",IF('角色卡'!AB18="牧師-Cleric","牧師",IF('角色卡'!AB18="德魯伊-Druid","德魯伊",IF('角色卡'!AB18="遊俠-Ranger","遊俠",IF('角色卡'!AB18="戰士-Fighter","戰士",IF('角色卡'!AB18="盜賊-Rogue","盜賊",IF('角色卡'!AB18="奇械師-Artificer","奇械師",""))))))))))))) | G8: 武僧-Monk | H8: 選擇2項：特技、運動、歷史、察言觀色、宗教、隱匿 | K8: 武僧-Monk | L8: 命流武者 | M8: 暗影武者 | N8: 四象武者 | O8: 散打武者 | P8: =IF('請先閱讀'!$O$27=true,"瘴癘武者","") | Q8: =IF('請先閱讀'!O28=true,"街頭武者","") | R8: =IF('請先閱讀'!$O$30=true,"天衡武者","") | S8: =IF('請先閱讀'!$O$31=true,"鉛冕武者","") | T8: =IF('請先閱讀'!$O$31=true,"孤高武者","") | U8: =IF('請先閱讀'!$O$31=true,"悔恨武者","") | V8: =IF('請先閱讀'!$O$33=true,"活體武器武者","") | W8: =IF('請先閱讀'!O35=true,"天界武者","")
B9: 聖 | C9: ='職業能力'!J2 -> 0 | E9: ='角色卡'!CE57 | G9: 聖騎士-Paladin | H9: 選擇2項：運動、察言觀色、威嚇、醫藥、說服、宗教 | K9: 聖騎士-Paladin | L9: 奉獻之誓 | M9: 榮耀之誓 | N9: 遠古之誓 | O9: 復仇之誓 | P9: =IF('請先閱讀'!F31=true,"巨靈貴族之誓","") -> 巨靈貴族之誓 | Q9: =IF('請先閱讀'!$O$27=true,"懲戒之誓","") | R9: =IF('請先閱讀'!O28=true,"狂歡之誓","") | S9: =IF('請先閱讀'!$O$30=true,"守護之誓","") | T9: =IF('請先閱讀'!$O$31=true,"瘟疫之誓","") | U9: =IF('請先閱讀'!$O$31=true,"屠戮之誓","") | V9: =IF('請先閱讀'!$O$31=true,"狂熱之誓","") | W9: =IF('請先閱讀'!O35=true,"爐火之誓","")
B10: 詭術師&嗜血竊賊 | C10: =IF(OR('角色卡'!AK57=L11,'角色卡'!BH57=L11,'角色卡'!CE57=L11,'角色卡'!AK57=V11,'角色卡'!BH57=V11,'角色卡'!CE57=V11),'職業能力'!M2,0) -> 0 | E10: =IF(OR('角色卡'!AB16=K13,'角色卡'!AB17=K13,'角色卡'!AB18=K13),"祈喚","") | G10: 遊俠-Ranger | H10: 選擇3項：動物馴服、運動、察言觀色、調查、自然、察覺、隱匿、求生 | K10: 遊俠-Ranger | L10: 獸王 | M10: 妖精漫遊者 | N10: 幽域追蹤者 | O10: 獵人 | P10: =IF('請先閱讀'!F31=true,"凜冬行者","") -> 凜冬行者 | Q10: =IF('請先閱讀'!$O$27=true,"晦暗先驅","") | R10: =IF('請先閱讀'!$O$30=true,"荒徑守護者","") | S10: =IF('請先閱讀'!$O$31=true,"綠林死神","") | T10: =IF('請先閱讀'!$O$31=true,"原初射手","") | U10: =IF('請先閱讀'!$O$31=true,"鼠群之王","") | V10: =IF('請先閱讀'!O35=true,"凜冬陷阱師","") | W10: =IF('請先閱讀'!O36=true,"大獸獵家","")
B11: 魔能騎士 | C11: =IF(OR('角色卡'!AK57="魔能騎士",'角色卡'!BH57="魔能騎士",'角色卡'!CE57="魔能騎士"),'職業能力'!F2,0) -> 0 | E11: 專長 | G11: 盜賊-Rogue | H11: 選擇4項：特技、運動、欺瞞、察言觀色、威嚇、調查、察覺、說服、巧手、隱匿 | K11: 盜賊-Rogue | L11: 詭術師 | M11: 刺客 | N11: 魂刃 | O11: 竊賊 | P11: =IF('請先閱讀'!F31=true,"三神使徒","") -> 三神使徒 | Q11: =IF('請先閱讀'!$O$27=true,"罪人","") | R11: =IF('請先閱讀'!O28=true,"蛛行者","") | S11: =IF('請先閱讀'!$O$30=true,"暗影行者","") | T11: =IF('請先閱讀'!$O$31=true,"響馬","") | U11: =IF('請先閱讀'!$O$31=true,"厄運使者","") | V11: =IF('請先閱讀'!$O$31=true,"嗜血竊賊","") | W11: =IF('請先閱讀'!O35=true,"符文塗鴉客","")
B12: 契 | C12: ='職業能力'!O2 -> 0 | E12: 其他 | G12: 術士-Sorcerer | H12: 選擇2項：奧秘、欺瞞、察言觀色、威嚇、說服、宗教 | K12: 術士-Sorcerer | L12: 畸變術法 | M12: 時械術法 | N12: 龍族術法 | O12: 狂野術法 | P12: =IF('請先閱讀'!F31=true,"咒火術法","") -> 咒火術法 | Q12: =IF('請先閱讀'!$O$27=true,"猩紅術法","") | R12: =IF('請先閱讀'!$O$30=true,"飢渴黑暗術法","") | S12: =IF('請先閱讀'!$O$31=true,"天啟術法","") | T12: =IF('請先閱讀'!$O$31=true,"幽靈術法","") | U12: =IF('請先閱讀'!$O$31=true,"悲慘血脈術法","") | V12: =IF('請先閱讀'!O35=true,"霜凍術法","")
B13: 施法等級 | C13: =C3+C4+C5+C6+C7+ROUNDUP(C8/2+C9/2+C15/2,0)+ROUNDUP((C10+C11+C16)/3,0) -> 3 | G13: 契術師-Warlock | H13: 選擇2項：奧秘、欺瞞、歷史、威嚇、調查、自然、宗教 | K13: 契術師-Warlock | L13: 至高妖精宗主 | M13: 天界宗主 | N13: 邪魔宗主 | O13: 舊日支配者宗主 | P13: =IF('請先閱讀'!$O$27=true,"愚神宗主","") | Q13: =IF('請先閱讀'!$O$27=true,"角之王宗主","") | R13: =IF('請先閱讀'!O28=true,"未來的你宗主","") | S13: =IF('請先閱讀'!$O$30=true,"崇高貓貓庭宗主","") | T13: =IF('請先閱讀'!$O$31=true,"鬼婆集會宗主","") | U13: =IF('請先閱讀'!$O$31=true,"吸血鬼先祖宗主","") | V13: =IF('請先閱讀'!$O$31=true,"宇宙寄生體宗主","") | W13: =IF('請先閱讀'!O35=true,"星界獅鷲獸宗主","")
B14: 契約魔法等級 | C14: =C12 -> 0 | G14: 法師-Wizard | H14: 選擇2項：奧秘、歷史、察言觀色、調查、醫藥、自然、宗教 | K14: 法師-Wizard | L14: 防護師 | M14: 預言師 | N14: 塑能師 | O14: 幻術師 | P14: =IF('請先閱讀'!F31=true,"劍詠師","") -> 劍詠師 | Q14: =IF('請先閱讀'!$O$27=true,"神祕學家","") | R14: =IF('請先閱讀'!$O$27=true,"賢者","") | S14: =IF('請先閱讀'!$O$30=true,"司書","") | T14: =IF('請先閱讀'!$O$31=true,"惡魔學家","") | U14: =IF('請先閱讀'!$O$31=true,"疫醫","") | V14: =IF('請先閱讀'!$O$31=true,"操血師","") | W14: =IF('請先閱讀'!O35=true,"塑形師","")
B15: 奇械師 | C15: ='職業能力'!A2 -> 0 | G15: 奇械師-Artificer | H15: 選擇2項：奧秘、歷史、調查、醫藥、自然、察覺、巧手 | K15: 奇械師-Artificer | L15: 煉金匠 | M15: 裝甲匠 | N15: 魔炮匠 | O15: 戰地工匠 | P15: 製圖匠 | Q15: =IF('請先閱讀'!$O$33=true,"鍛造匠","") | R15: =IF('請先閱讀'!$O$33=true,"獨行匠","")
B16: 咒槍客 | C16: =IF(OR('角色卡'!AK57="咒槍客",'角色卡'!BH57="咒槍客",'角色卡'!CE57="咒槍客"),'職業能力'!G2,0) -> 0 | G16: 銃士-Gunslinger | H16: 選擇2項：特技、動物馴服、運動、欺瞞、察言觀色、威嚇、察覺、說服、巧手、隱匿 | K16: 銃士-Gunslinger | L16: 銳眼客 | M16: 豪賭客 | N16: 密間客 | O16: 咒槍客 | P16: 花槍客 | Q16: 白帽客
B17: 神祕學家公會 | C17: =IF(OR('角色卡'!AK57=N17,'角色卡'!BH57=N17,'角色卡'!CE57=N17),'職業能力'!I2,0) -> 0 | G17: 怪物獵人-Monster Hunter | H17: 選擇3項：運動、歷史、調查、醫藥、自然、察覺、宗教、求生 | K17: 怪物獵人-Monster Hunter | L17: 肢解者公會 | M17: 吞噬者公會 | N17: 神祕學家公會 | O17: 捕獸者公會
G18: 拳鬥士-Pugilist | H18: 選擇2項：特技、運動、欺瞞、威嚇、察覺、巧手、隱匿 | K18: 拳鬥士-Pugilist | L18: 狗與獵犬 | M18: 恐懼之手 | N18: 粗鄙之人 | O18: 擂台摔角 | P18: 街頭聖徒 | Q18: 甜蜜科學
B20: 職業Ⅰ子職 | C20: 職業Ⅱ子職 | D20: 職業Ⅲ子職 | F20: 職業Ⅰ能力 | G20: 職業Ⅱ能力 | H20: 職業Ⅲ能力 | J20: 職業Ⅰ子職能力 | K20: 職業Ⅱ子職能力 | L20: 職業Ⅲ子職能力 | N20: 物種血脈 | O20: 物種血脈列表
B21: =ifna(VLOOKUP('角色卡'!$AB16,$K$3:$X$18,2,false),"") -> 防護師 | C21: =ifna(VLOOKUP('角色卡'!$AB17,$K$3:$X$18,2,false),"") | D21: =ifna(VLOOKUP('角色卡'!$AB18,$K$3:$X$18,2,false),"") | F21: =ifna(HLOOKUP('角色卡'!AB16,'職業能力'!$A$1:$P$21,3,false),"") -> 施法 | G21: =ifna(HLOOKUP('角色卡'!AB17,'職業能力'!$A$1:$P$21,3,false),"") | H21: =ifna(HLOOKUP('角色卡'!$AB$18,'職業能力'!$A$1:$P$21,3,false),"") | J21: =IFNA(VLOOKUP('角色卡'!$AK$57,'子職業能力'!$B$2:$J$291,2,FALSE),"") -> 劍歌 | K21: =IFNA(VLOOKUP('角色卡'!$BH$57,'子職業能力'!$B$2:$J$291,2,FALSE),"") | L21: =IFNA(VLOOKUP('角色卡'!$CE$57,'子職業能力'!$B$2:$J$291,2,FALSE),"") | N21: =IFNA(VLOOKUP('角色卡'!$Y$7,$O$21:$Y$31,2,FALSE),"") | O21: 龍裔 Dragonborn | P21: 黑龍 Black | Q21: 藍龍 Blue | R21: 綠龍 Green | S21: 紅龍 Red | T21: 白龍 White | U21: 金龍 Gold | V21: 銀龍 Silver | W21: 黃銅龍 Brass | X21: 青銅龍 Bronze | Y21: 赤銅龍 Copper
B22: =ifna(VLOOKUP('角色卡'!$AB16,$K$3:$X$18,3,false),"") -> 預言師 | C22: =ifna(VLOOKUP('角色卡'!$AB17,$K$3:$X$18,3,false),"") | D22: =ifna(VLOOKUP('角色卡'!$AB18,$K$3:$X$18,3,false),"") | F22: =ifna(HLOOKUP('角色卡'!AB16,'職業能力'!$A$1:$P$21,4,false),"") -> 儀式學家 | G22: =ifna(HLOOKUP('角色卡'!AB17,'職業能力'!$A$1:$P$21,4,false),"") | H22: =ifna(HLOOKUP('角色卡'!$AB$18,'職業能力'!$A$1:$P$21,4,false),"") | J22: =IFNA(VLOOKUP('角色卡'!$AK$57,'子職業能力'!$B$2:$J$291,3,FALSE),"") -> 戰歌訓練 | K22: =IFNA(VLOOKUP('角色卡'!$BH$57,'子職業能力'!$B$2:$J$291,3,FALSE),"") | L22: =IFNA(VLOOKUP('角色卡'!$CE$57,'子職業能力'!$B$2:$J$291,3,FALSE),"") | N22: =IFNA(VLOOKUP('角色卡'!$Y$7,$O$21:$Y$31,3,FALSE),"") | O22: 精靈 Elf | P22: 卓爾 Drow | Q22: 高等精靈 High Elf | R22: 木精靈 Wood Elf | S22: =if('請先閱讀'!F32=true,"格溫精靈 Lorwyn Elf","") -> 格溫精靈 Lorwyn Elf | T22: =if('請先閱讀'!F32=true,"暗影荒原精靈 Shadowmoor Elf","") -> 暗影荒原精靈 Shadowmoor Elf
B23: =ifna(VLOOKUP('角色卡'!$AB16,$K$3:$X$18,4,false),"") -> 塑能師 | C23: =ifna(VLOOKUP('角色卡'!$AB17,$K$3:$X$18,4,false),"") | D23: =ifna(VLOOKUP('角色卡'!$AB18,$K$3:$X$18,4,false),"") | F23: =ifna(HLOOKUP('角色卡'!AB16,'職業能力'!$A$1:$P$21,5,false),"") -> 奧術恢復(2個環位) | G23: =ifna(HLOOKUP('角色卡'!AB17,'職業能力'!$A$1:$P$21,5,false),"") | H23: =ifna(HLOOKUP('角色卡'!$AB$18,'職業能力'!$A$1:$P$21,5,false),"") | J23: =IFNA(VLOOKUP('角色卡'!$AK$57,'子職業能力'!$B$2:$J$291,4,FALSE),"") | K23: =IFNA(VLOOKUP('角色卡'!$BH$57,'子職業能力'!$B$2:$J$291,4,FALSE),"") | L23: =IFNA(VLOOKUP('角色卡'!$CE$57,'子職業能力'!$B$2:$J$291,4,FALSE),"") | N23: =IFNA(VLOOKUP('角色卡'!$Y$7,$O$21:$Y$31,4,FALSE),"") | O23: 地侏 Gnome | P23: 林地侏 Forest Gnome | Q23: 岩地侏 Rock Gnome
B24: =ifna(VLOOKUP('角色卡'!$AB16,$K$3:$X$18,5,false),"") -> 幻術師 | C24: =ifna(VLOOKUP('角色卡'!$AB17,$K$3:$X$18,5,false),"") | D24: =ifna(VLOOKUP('角色卡'!$AB18,$K$3:$X$18,5,false),"") | F24: =ifna(HLOOKUP('角色卡'!AB16,'職業能力'!$A$1:$P$21,6,false),"") -> 學者 | G24: =ifna(HLOOKUP('角色卡'!AB17,'職業能力'!$A$1:$P$21,6,false),"") | H24: =ifna(HLOOKUP('角色卡'!$AB$18,'職業能力'!$A$1:$P$21,6,false),"") | J24: =IFNA(VLOOKUP('角色卡'!$AK$57,'子職業能力'!$B$2:$J$291,5,FALSE),"") | K24: =IFNA(VLOOKUP('角色卡'!$BH$57,'子職業能力'!$B$2:$J$291,5,FALSE),"") | L24: =IFNA(VLOOKUP('角色卡'!$CE$57,'子職業能力'!$B$2:$J$291,5,FALSE),"") | N24: =IFNA(VLOOKUP('角色卡'!$Y$7,$O$21:$Y$31,5,FALSE),"") | O24: 歌利亞 Goliath | P24: 雲巨人 Cloud Giant | Q24: 火巨人 Fire Giant | R24: 霜巨人 Frost Giant | S24: 山丘巨人 Hill Giant | T24: 石巨人 Stone Giant | U24: 風暴巨人 Storm Giant
B25: =ifna(VLOOKUP('角色卡'!$AB16,$K$3:$X$18,6,false),"") -> 劍詠師 | C25: =ifna(VLOOKUP('角色卡'!$AB17,$K$3:$X$18,6,false),"") | D25: =ifna(VLOOKUP('角色卡'!$AB18,$K$3:$X$18,6,false),"") | F25: =ifna(HLOOKUP('角色卡'!AB16,'職業能力'!$A$1:$P$21,7,false),"") | G25: =ifna(HLOOKUP('角色卡'!AB17,'職業能力'!$A$1:$P$21,7,false),"") | H25: =ifna(HLOOKUP('角色卡'!$AB$18,'職業能力'!$A$1:$P$21,7,false),"") | J25: =IFNA(VLOOKUP('角色卡'!$AK$57,'子職業能力'!$B$2:$J$291,6,FALSE),"") | K25: =IFNA(VLOOKUP('角色卡'!$BH$57,'子職業能力'!$B$2:$J$291,6,FALSE),"") | L25: =IFNA(VLOOKUP('角色卡'!$CE$57,'子職業能力'!$B$2:$J$291,6,FALSE),"") | N25: =IFNA(VLOOKUP('角色卡'!$Y$7,$O$21:$Y$31,6,FALSE),"") | O25: 提夫林 Tiefling | P25: 深淵 Abyssal | Q25: 幽冥 Chthonic | R25: 煉獄 Infernal
B26: =ifna(VLOOKUP('角色卡'!$AB16,$K$3:$X$18,7,false),"") | C26: =ifna(VLOOKUP('角色卡'!$AB17,$K$3:$X$18,7,false),"") | D26: =ifna(VLOOKUP('角色卡'!$AB18,$K$3:$X$18,7,false),"") | F26: =ifna(HLOOKUP('角色卡'!AB16,'職業能力'!$A$1:$P$21,8,false),"") | G26: =ifna(HLOOKUP('角色卡'!AB17,'職業能力'!$A$1:$P$21,8,false),"") | H26: =ifna(HLOOKUP('角色卡'!$AB$18,'職業能力'!$A$1:$P$21,8,false),"") | J26: =IFNA(VLOOKUP('角色卡'!$AK$57,'子職業能力'!$B$2:$J$291,7,FALSE),"") | K26: =IFNA(VLOOKUP('角色卡'!$BH$57,'子職業能力'!$B$2:$J$291,7,FALSE),"") | L26: =IFNA(VLOOKUP('角色卡'!$CE$57,'子職業能力'!$B$2:$J$291,7,FALSE),"") | N26: =IFNA(VLOOKUP('角色卡'!$Y$7,$O$21:$Y$31,7,FALSE),"") | O26: 仙靈 Faerie | P26: =if('請先閱讀'!F32=true,"格溫 Lorwyn","") -> 格溫 Lorwyn | Q26: =if('請先閱讀'!F32=true,"暗影荒原 Shadowmoor","") -> 暗影荒原 Shadowmoor
B27: =ifna(VLOOKUP('角色卡'!$AB16,$K$3:$X$18,8,false),"") | C27: =ifna(VLOOKUP('角色卡'!$AB17,$K$3:$X$18,8,false),"") | D27: =ifna(VLOOKUP('角色卡'!$AB18,$K$3:$X$18,8,false),"") | F27: =ifna(HLOOKUP('角色卡'!AB16,'職業能力'!$A$1:$P$21,9,false),"") | G27: =ifna(HLOOKUP('角色卡'!AB17,'職業能力'!$A$1:$P$21,9,false),"") | H27: =ifna(HLOOKUP('角色卡'!$AB$18,'職業能力'!$A$1:$P$21,9,false),"") | J27: =IFNA(VLOOKUP('角色卡'!$AK$57,'子職業能力'!$B$2:$J$291,8,FALSE),"") | K27: =IFNA(VLOOKUP('角色卡'!$BH$57,'子職業能力'!$B$2:$J$291,8,FALSE),"") | L27: =IFNA(VLOOKUP('角色卡'!$CE$57,'子職業能力'!$B$2:$J$291,8,FALSE),"") | N27: =IFNA(VLOOKUP('角色卡'!$Y$7,$O$21:$Y$31,8,FALSE),"") | O27: 潔英 Kithkin | P27: =if('請先閱讀'!F32=true,"格溫 Lorwyn","") -> 格溫 Lorwyn | Q27: =if('請先閱讀'!F32=true,"暗影荒原 Shadowmoor","") -> 暗影荒原 Shadowmoor
B28: =ifna(VLOOKUP('角色卡'!$AB$16,$K$3:$X$18,9,false),"") | C28: =ifna(VLOOKUP('角色卡'!$AB$17,$K$3:$X$18,9,false),"") | D28: =ifna(VLOOKUP('角色卡'!$AB$18,$K$3:$X$18,9,false),"") | F28: =ifna(HLOOKUP('角色卡'!AB16,'職業能力'!$A$1:$P$21,10,false),"") | G28: =ifna(HLOOKUP('角色卡'!AB17,'職業能力'!$A$1:$P$21,10,false),"") | H28: =ifna(HLOOKUP('角色卡'!$AB$18,'職業能力'!$A$1:$P$21,10,false),"") | J28: =IFNA(VLOOKUP('角色卡'!$AK$57,'子職業能力'!$B$2:$J$291,9,FALSE),"") | K28: =IFNA(VLOOKUP('角色卡'!$BH$57,'子職業能力'!$B$2:$J$291,9,FALSE),"") | L28: =IFNA(VLOOKUP('角色卡'!$CE$57,'子職業能力'!$B$2:$J$291,9,FALSE),"") | N28: =IFNA(VLOOKUP('角色卡'!$Y$7,$O$21:$Y$31,9,FALSE),"") | O28: 吉佩廷 Geppettin | P28: 瓷娃娃 Bisque | Q28: 傀儡 Marionette | R28: 絨毛玩具 Plushie
B29: =ifna(VLOOKUP('角色卡'!$AB16,$K$3:$X$18,10,false),"") | C29: =ifna(VLOOKUP('角色卡'!$AB17,$K$3:$X$18,10,false),"") | D29: =ifna(VLOOKUP('角色卡'!$AB18,$K$3:$X$18,10,false),"") | F29: =ifna(HLOOKUP('角色卡'!AB16,'職業能力'!$A$1:$P$21,11,false),"") | G29: =ifna(HLOOKUP('角色卡'!AB17,'職業能力'!$A$1:$P$21,11,false),"") | H29: =ifna(HLOOKUP('角色卡'!$AB$18,'職業能力'!$A$1:$P$21,11,false),"") | N29: =IFNA(VLOOKUP('角色卡'!$Y$7,$O$21:$Y$31,10,FALSE),"") | O29: 曼德拉 Mandrake | P29: 春季 Spring | Q29: 夏季 Summer | R29: 秋季 Autumn | S29: 冬季 Winter
B30: =ifna(VLOOKUP('角色卡'!$AB$16,$K$3:$X$18,11,false),"") | C30: =ifna(VLOOKUP('角色卡'!$AB$17,$K$3:$X$18,11,false),"") | D30: =ifna(VLOOKUP('角色卡'!$AB$18,$K$3:$X$18,11,false),"") | F30: =ifna(HLOOKUP('角色卡'!AB16,'職業能力'!$A$1:$P$21,12,false),"") | G30: =ifna(HLOOKUP('角色卡'!AB17,'職業能力'!$A$1:$P$21,12,false),"") | H30: =ifna(HLOOKUP('角色卡'!$AB$18,'職業能力'!$A$1:$P$21,12,false),"") | N30: =IFNA(VLOOKUP('角色卡'!$Y$7,$O$21:$Y$31,11,FALSE),"") | O30: 阿斯莫 Aasimar | P30: 費尼亞 Fernian | Q30: 瑪巴爾 Mabaran
B31: =ifna(VLOOKUP('角色卡'!$AB$16,$K$3:$X$18,12,false),"") | C31: =ifna(VLOOKUP('角色卡'!$AB$17,$K$3:$X$18,12,false),"") | D31: =ifna(VLOOKUP('角色卡'!$AB$18,$K$3:$X$18,12,false),"") | F31: =ifna(HLOOKUP('角色卡'!AB16,'職業能力'!$A$1:$P$21,13,false),"") | G31: =ifna(HLOOKUP('角色卡'!AB17,'職業能力'!$A$1:$P$21,13,false),"") | H31: =ifna(HLOOKUP('角色卡'!$AB$18,'職業能力'!$A$1:$P$21,13,false),"") | O31: 羽裔 Feathren | P31: (太麻煩了自己填吧)
B32: =ifna(VLOOKUP('角色卡'!$AB$16,$K$3:$X$18,13,false),"") | C32: =ifna(VLOOKUP('角色卡'!$AB$17,$K$3:$X$18,13,false),"") | D32: =ifna(VLOOKUP('角色卡'!$AB$18,$K$3:$X$18,13,false),"") | F32: =ifna(HLOOKUP('角色卡'!AB16,'職業能力'!$A$1:$P$21,14,false),"") | G32: =ifna(HLOOKUP('角色卡'!AB17,'職業能力'!$A$1:$P$21,14,false),"") | H32: =ifna(HLOOKUP('角色卡'!$AB$18,'職業能力'!$A$1:$P$21,14,false),"") | J32: DC | K32: 命中 | L32: 調整值
B33: =ifna(VLOOKUP('角色卡'!$AB$16,$K$3:$X$18,14,false),"") | C33: =ifna(VLOOKUP('角色卡'!$AB$17,$K$3:$X$18,14,false),"") | D33: =ifna(VLOOKUP('角色卡'!$AB$18,$K$3:$X$18,14,false),"") | F33: =ifna(HLOOKUP('角色卡'!AB16,'職業能力'!$A$1:$P$21,15,false),"") | G33: =ifna(HLOOKUP('角色卡'!AB17,'職業能力'!$A$1:$P$21,15,false),"") | H33: =ifna(HLOOKUP('角色卡'!$AB$18,'職業能力'!$A$1:$P$21,15,false),"") | J33: =IFNA(VLOOKUP('角色卡'!$BW33,'角色卡'!$C$15:$L$20,8,FALSE)+'角色卡'!$C$47+'角色卡'!$BZ33+8,"") -> 13 | K33: =IFNA(VLOOKUP('角色卡'!$BW33,'角色卡'!$C$15:$L$20,8,FALSE)+'角色卡'!$C$47+'角色卡'!$BZ33,"") -> 5 | L33: =IFNA(VLOOKUP('角色卡'!$BW33,'角色卡'!$C$15:$L$20,8,FALSE)+'角色卡'!$BZ33,"") -> 3
F34: =ifna(HLOOKUP('角色卡'!AB16,'職業能力'!$A$1:$P$21,16,false),"") | G34: =ifna(HLOOKUP('角色卡'!AB17,'職業能力'!$A$1:$P$21,16,false),"") | H34: =ifna(HLOOKUP('角色卡'!$AB$18,'職業能力'!$A$1:$P$21,16,false),"") | J34: =IFNA(VLOOKUP('角色卡'!$BW34,'角色卡'!$C$15:$L$20,8,FALSE)+'角色卡'!$C$47+'角色卡'!$BZ34+8,"") | K34: =IFNA(VLOOKUP('角色卡'!$BW34,'角色卡'!$C$15:$L$20,8,FALSE)+'角色卡'!$C$47+'角色卡'!$BZ34,"") | L34: =IFNA(VLOOKUP('角色卡'!$BW34,'角色卡'!$C$15:$L$20,8,FALSE)+'角色卡'!$BZ34,"")
F35: =ifna(HLOOKUP('角色卡'!AB16,'職業能力'!$A$1:$P$21,17,false),"") | G35: =ifna(HLOOKUP('角色卡'!AB17,'職業能力'!$A$1:$P$21,17,false),"") | H35: =ifna(HLOOKUP('角色卡'!$AB$18,'職業能力'!$A$1:$P$21,17,false),"") | J35: =IFNA(VLOOKUP('角色卡'!$BW35,'角色卡'!$C$15:$L$20,8,FALSE)+'角色卡'!$C$47+'角色卡'!$BZ35+8,"") | K35: =IFNA(VLOOKUP('角色卡'!$BW35,'角色卡'!$C$15:$L$20,8,FALSE)+'角色卡'!$C$47+'角色卡'!$BZ35,"") | L35: =IFNA(VLOOKUP('角色卡'!$BW35,'角色卡'!$C$15:$L$20,8,FALSE)+'角色卡'!$BZ35,"")
F36: =ifna(HLOOKUP('角色卡'!AB16,'職業能力'!$A$1:$P$21,18,false),"") | G36: =ifna(HLOOKUP('角色卡'!AB17,'職業能力'!$A$1:$P$21,18,false),"") | H36: =ifna(HLOOKUP('角色卡'!$AB$18,'職業能力'!$A$1:$P$21,18,false),"")
F37: =ifna(HLOOKUP('角色卡'!AB16,'職業能力'!$A$1:$P$21,19,false),"") | G37: =ifna(HLOOKUP('角色卡'!AB17,'職業能力'!$A$1:$P$21,19,false),"") | H37: =ifna(HLOOKUP('角色卡'!$AB$18,'職業能力'!$A$1:$P$21,19,false),"") | J37: 召喚物熟練項 | K37: 物種索引
F38: =ifna(HLOOKUP('角色卡'!AB16,'職業能力'!$A$1:$P$21,20,false),"") | G38: =ifna(HLOOKUP('角色卡'!AB17,'職業能力'!$A$1:$P$21,20,false),"") | H38: =ifna(HLOOKUP('角色卡'!$AB$18,'職業能力'!$A$1:$P$21,20,false),"") | J38: =IFNA(VLOOKUP('坐騎召喚物'!C3,'召喚物資料'!B3:Z1003,25,FALSE),"") | K38: =LEFT('角色卡'!Y7,3) -> 人類
B40: 魔能祈喚 | D40: 召喚物類型 | E40: 召喚物 | F40: 召喚物法術列表 | L40: 工匠工具熟練項
B41: =IF($C$12>=2,"痛苦衝擊","") | D41: =IFNA(VLOOKUP('坐騎召喚物'!M4,F41:J67,2,FALSE),"") | F41: 坐騎 | L41: 樂器(通用) | M41: 魅力
B42: 暗影護甲 | D42: =IFNA(VLOOKUP('坐騎召喚物'!M4,F41:J67,3,FALSE),"") | F42: 尋獲魔寵 | L42: 煉金工具 | M42: 智力
B43: =IF($C$12>=5,"躍升步伐","") | D43: =IFNA(VLOOKUP('坐騎召喚物'!M4,F41:J67,4,FALSE),"") | E43: =IF('坐騎召喚物'!$M$4="尋獲魔寵",IF(COUNTIF('職業能力選項'!$BE$3:$BE$12,"鎖鏈魔契")>0,'魔寵資料'!$B4,""),IF('坐騎召喚物'!$M$4="坐騎",'坐騎資料'!B4,"異界坐騎")) -> 異界坐騎 | F43: 尋獲坐騎 | G43: 天界生物Celestials | H43: 精類Fey | I43: 邪魔Fiends | L43: 釀酒工具 | M43: 智力
...

Sheet 物種
A1: 物種 | B1: 出處 | C1: 體型 | D1: 生物類型 | E1: 能力A | F1: 能力B | G1: 能力C | H1: 能力D | I1: 能力E | J1: 能力F | K1: 能力G | L1: 能力H
A2: 阿斯莫 Aasimar | B2: PHB | C2: 中型 | D2: 類人生物 | E2: 黑暗視覺 Darkvision | F2: =IF('角色卡'!$AP$7='索引資料'!P30,"費尼亞抗性 Fernian Resistance","天界抗性 Celestial Resistance") -> 天界抗性 Celestial Resistance | G2: 治癒之手 Healing Hands | H2: =IF('角色卡'!$AP$7='索引資料'!P30,"烈火掌者 Fire Bearer",IF('角色卡'!$AP$7='索引資料'!Q30,"亡者高呼 Herald of Death","光輝掌者 Light Bearer")) -> 光輝掌者 Light Bearer | I2: 天界啟示 Celestical Revelation
A3: 龍裔 Dragonborn | B3: PHB | C3: 中型 | D3: 類人生物 | E3: 黑暗視覺 Darkvision | F3: ="龍族血統："&'角色卡'!AP7&" Draconic Ancestry" -> 龍族血統： Draconic Ancestry | G3: 吐息武器 Breath Weapon | H3: 傷害抗性 Damage Resistance | I3: 龍族飛翼 Draconic Flight
A4: 矮人 Dwarf | B4: PHB | C4: 中型 | D4: 類人生物 | E4: 黑暗視覺 Darkvision | F4: 矮人體魄 Dwarven Resilience | G4: 矮人剛毅 Dwarven Toughness | H4: 岩石敏銳 Stonecunning
A5: 精靈 Elf | B5: PHB | C5: 中型 | D5: 類人生物 | E5: 黑暗視覺 Darkvision | F5: ="精靈血脈："&'角色卡'!AP7&" Elven Lineage" -> 精靈血脈： Elven Lineage | G5: 精類血統 Fey Ancestry | H5: 敏銳感官 Keen Senses | I5: 傳思 Trance
A6: 地侏 Gnome | B6: PHB | C6: 小型 | D6: 類人生物 | E6: 黑暗視覺 Darkvision | F6: 地侏狡黠 Gnome Cunning | G6: ="地侏血脈："&'角色卡'!AP7&" Elven Lineage" -> 地侏血脈： Elven Lineage
A7: 歌利亞 Goliath | B7: PHB | C7: 中型 | D7: 類人生物 | E7: ="巨人血統："&'角色卡'!AP7&" Giant Ancestry" -> 巨人血統： Giant Ancestry | F7: 大型形態 Large Form | G7: 身強力壯 Powerful Build
A8: 半身人 Halfling | B8: PHB | C8: 小型 | D8: 類人生物 | E8: 勇氣 Brave | F8: 半身人靈巧 Halfling Nimbleness | G8: 幸運 Lucky | H8: 天生善匿 Naturally Stealthy
A9: 人類 Human | B9: PHB | C9: 中型or小型 | D9: 類人生物 | E9: 創造力 Resourceful | F9: 技能熟練 Skillful | G9: 多才多藝 Versatile
A10: 獸人 Orc | B10: PHB | C10: 中型 | D10: 類人生物 | E10: 黑暗視覺 Darkvision | F10: 激昂衝鋒 Adrenaline Rush | G10: 堅韌不屈 Relentless Endurance
A11: 提夫林 Tiefling | B11: PHB | C11: 中型or小型 | D11: 類人生物 | E11: 黑暗視覺 Darkvision | F11: ="邪魔遺贈："&'角色卡'!AP7&" Fiendish Legacy" -> 邪魔遺贈： Fiendish Legacy | G11: 異界存在 Otherworldly Presence
A12: =if('請先閱讀'!F32=true,"博格特 Boggart","") -> 博格特 Boggart | B12: LFL | C12: 小型 | D12: 類人生物 | E12: 黑暗視覺 Darkvision | F12: 精類血統 Fey Ancestry | G12: 小個子怒火 Fury of the Small | H12: 迅捷逃逸 Nimble Escape
A13: =if('請先閱讀'!F32=true,"仙靈 Faerie","") -> 仙靈 Faerie | B13: LFL | C13: 小型 | D13: 精類 | E13: 仙靈魔法 Fairy Magic | F13: 飛行 Flight | G13: =IFNA(IF('角色卡'!AO7='索引資料'!P26,"黑暗視覺 Darkvision",""),"")
A14: =if('請先閱讀'!F32=true,"炎親 Flamekin","") -> 炎親 Flamekin | B14: LFL | C14: 中型or小型 | D14: 類人生物 | E14: 黑暗視覺 Darkvision | F14: 火焰抗性 Fire Resistance | G14: 列焰之觸 Reach to the Blaze
A15: =if('請先閱讀'!F32=true,"潔英 Kithkin","") -> 潔英 Kithkin | B15: LFL | C15: 小型 | D15: 類人生物 | E15: 勇氣 Brave | F15: 半身人靈巧 Halfling Nimbleness | G15: 幸運 Lucky | H15: 天生善匿 Naturally Stealthy | I15: =IFNA(IF('角色卡'!AO7='索引資料'!P27,"黑暗視覺 Darkvision",""),"")
A16: =if('請先閱讀'!F32=true,"洛溫幻身靈 Lorwyn Changeling","") -> 洛溫幻身靈 Lorwyn Changeling | B16: LFL | C16: 中型or小型 | D16: 精類 | E16: 黑暗視覺 Darkvision | F16: 變換自身 Shape Self | G16: 歡笑模仿 Delightful Imitator
A17: =if('請先閱讀'!F32=true,"霜親 Rimekin","") -> 霜親 Rimekin | B17: LFL | C17: 中型or小型 | D17: 類人生物 | E17: 黑暗視覺 Darkvision | F17: 冷燃魔法 Cold Fire Magic | G17: 寒冷抗性 Cold Resistance
A18: =if('請先閱讀'!F33=true,"半血裔 Dhampir","") -> 半血裔 Dhampir | B18: ABoH | C18: 中型or小型 | D18: 類人生物 | E18: 黑暗視覺 Darkvision | F18: 蛛行 Spider Climb | G18: 不死痕跡 Trace of Undeath | H18: 吸血啃咬 Vampiric Bite
A19: =if('請先閱讀'!$F$34=true,"幻身靈 Changeling","") -> 幻身靈 Changeling | B19: EFA | C19: 中型or小型 | D19: 精類 | E19: 幻身靈本能 Changeling Instincts | F19: 變形者 Shape-Shifter
A20: =if('請先閱讀'!$F$34=true,"離夢人 Kalashtar","") -> 離夢人 Kalashtar | B20: EFA | C20: 中型 | D20: 異怪 | E20: 雙重意識 Dual Mind | F20: 心靈紀律 Mental Discipline | G20: 心靈連接 Mind Link | H20: 隔離夢境 Severed from Dreams
A21: =if('請先閱讀'!$F$34=true,"混血精靈 Khoravar","") -> 混血精靈 Khoravar | B21: EFA | C21: 中型or小型 | D21: 類人生物 | E21: 精類血統 Fey Ancestry | F21: 妖精餽贈 Fey Gift | G21: 昏睡韌性 Lethargy Resilience | H21: 才華橫溢 Skill Versatility
A22: =if('請先閱讀'!$F$34=true,"化獸者 Shifter","") -> 化獸者 Shifter | B22: EFA | C22: 中型or小型 | D22: 類人生物 | E22: 黑暗視覺 Darkvision | F22: 獸性本能 Bestial Instincts | G22: 化形 Shifting
A23: =if('請先閱讀'!$F$34=true,"戰俑 Warforged","") -> 戰俑 Warforged | B23: EFA | C23: 中型or小型 | D23: 構裝體 | E23: 構裝韌性 Construct Resilience | F23: 一體化防護 Integrated Protection | G23: 哨兵式休息 Sentry's Rest | H23: 特化設計 Specialized Design | I23: 不倦 Tireless
A24: =IF('請先閱讀'!$O$27=true,"灰燼裔 Ashborn","") | B24: ='請先閱讀'!M$27 -> TCM | C24: 小型 | D24: 邪魔 | E24: 灰燼遺贈 Ashen Legacy | F24: 黑暗視覺 Darkvision | G24: 邪魔幸運 Fiendish Fortune | H24: 蠍刺 Scorpion Sting
A25: =IF('請先閱讀'!$O$27=true,"蒼羽裔 Azureborn","") | B25: ='請先閱讀'!M$27 -> TCM | C25: 中型 | D25: 類人生物 | E25: 蒼羽遺贈 Azure Legacy | F25: 黑暗視覺 Darkvision | G25: 窺視命運 Glimpse Fate | H25: 魔法之風 Winds of Magic
A26: =IF('請先閱讀'!$O$27=true,"沼澤裔 Ashborn","") | B26: ='請先閱讀'!M$27 -> TCM | C26: 中型 | D26: 巨人 | E26: 沼澤巨體 Bog Bulk | F26: 黑暗視覺 Darkvision | G26: 引導連結 Guiding Bond | H26: 敏銳感官 Keen Senses | I26: 再生 Regeneration
A27: =IF('請先閱讀'!$O$27=true,"咒狼裔 Curseborn","") | B27: ='請先閱讀'!M$27 -> TCM | C27: 中型 | D27: 類人生物 | E27: 詛咒利爪 Cursed Claws | F27: 黑暗視覺 Darkvision | G27: 灰厄平衡 Grey Balance | H27: 狼族感官 Lupine Sense
A28: =IF('請先閱讀'!$O$27=true,"深潛裔 Deepborn","") | B28: ='請先閱讀'!M$27 -> TCM | C28: 中型 | D28: 異怪 | E28: 兩棲 Amphibious | F28: 黑暗視覺 Darkvision | G28: 異界亂語 Eldritch Gibbering | H28: 無盡食慾 Endless Hunger
A29: =IF('請先閱讀'!$O$27=true,"詭木裔 Gnarlborn","") | B29: ='請先閱讀'!M$27 -> TCM | C29: 中型 | D29: 植物 | E29: 根深蒂固 Deep Roots | F29: 神木低語 Elderwood Whispers | G29: 纏枝 Grasping Branches | H29: 樹根感知 Root Sense | I29: 參天之姿 Towering Size
A30: =IF('請先閱讀'!$O$27=true,"霜墓裔 Graveborn","") | B30: ='請先閱讀'!M$27 -> TCM | C30: 中型 | D30: 不死生物 | E30: 黑暗視覺 Darkvision | F30: 吞食屍體 Devour Corpse | G30: 無懼霜寒 Frozen Waste | H30: 駐魔龍鋼 Infused Drakkonite
A31: =IF('請先閱讀'!$O$27=true,"豐收裔 Harvestborn","") | B31: ='請先閱讀'!M$27 -> TCM | C31: 中型 | D31: 構裝體 | E31: 剔除 Culling | F31: 翠綠贈禮 Gift of the Green | G31: 南瓜燈 Jack-O-Lantern | H31: 稻草人本質 Scarecrow Nature | I31: 守望休憩 Watchful Rest
A32: =IF('請先閱讀'!$O$27=true,"疫鼠裔 Plagueborn","") | B32: ='請先閱讀'!M$27 -> TCM | C32: 中型 | D32: 類人生物 | E32: 汙穢之子 Born in Filth | F32: 黑暗視覺 Darkvision | G32: 染疫狡詐 Infected Cunning | H32: 帶原體 Plague Bearer
A33: =IF('請先閱讀'!$O$27=true,"遺骷裔 Relicborn","") | B33: ='請先閱讀'!M$27 -> TCM | C33: 中型 | D33: 不死生物 | E33: 死亡之舞 Dance of Death | F33: 永恆派對 Eternal Party | G33: 紀念之刻 Moment of Remembrance | H33: 狂歡之魂 Soul of Revelry
A34: =IF('請先閱讀'!$O$27=true,"絲蛛裔 Silkborn","") | B34: ='請先閱讀'!M$27 -> TCM | C34: 中型 | D34: 類人生物 | E34: 珠寶甲殼 Bejeweled Carapace | F34: 黑暗視覺 Darkvision | G34: 蛛絲遺贈 Silken Legacy | H34: 蛛行 Spider Climb
A35: =IF('請先閱讀'!$O$27=true,"石像裔 Stoneborn","") | B35: ='請先閱讀'!M$27 -> TCM | C35: 中型or小型 | D35: 構裝體 | E35: 銀輝 Argent Gleam | F35: 白銀壁壘 Silver Bulwark | G35: 守望感官 Watchful Senses
A36: =IF('請先閱讀'!$O$27=true,"絲偶裔 Threadborn","") | B36: ='請先閱讀'!M$27 -> TCM | C36: 中型 | D36: 構裝體 | E36: 球形關節 Ball-Jointed | F36: 純潔心智 Innocent Mind | G36: 絲線天性 Sewn Nature | H36: 撫慰之心 Soothing Heart | I36: 常伴左右 You've Got a Friend
A37: =IF('請先閱讀'!O28=true,"吉佩廷 Geppettin","") | B37: VSS:PP | C37: 中型or小型 | D37: 構裝體 | E37: 黑暗視覺 Darkvision | F37: 構裝天性 Construct Nature | G37: 精緻手工 Handcrafted Quality | H37: ="吉佩廷構造："&'角色卡'!AP7&" Gepettin Construction" -> 吉佩廷構造： Gepettin Construction
A38: =IF('請先閱讀'!O28=true,"曼德拉 Mandrake","") | B38: VSS:PP | C38: 中型 | D38: 植物 | E38: 植物天性 Plant Nature | F38: 自然連結 Natural Connection | G38: 根源魔法 Root Magic | H38: 纏繞藤蔓 Entangling Vines
A39: =IF('請先閱讀'!$O$31=true,"GH龍裔 Dragonborn","") | B39: GH | C39: 中型 | D39: 類人生物 | E39: 吐息武器 Breath Weapon | F39: 傷害抗性 Damage Resistance | G39: 威攝咆哮 Menacing Roar | H39: 黑暗視覺 Darkvision | I39: 野外行動 Natural Movement | J39: 強力體格 Powerful Build | K39: 堅定威儀 Firm Influence | L39: 信仰感召 Moved by Faith
A40: =IF('請先閱讀'!$O$31=true,"GH矮人 Dwarf","") | B40: GH | C40: 中型 | D40: 類人生物 | E40: 傷害抗性(毒) Damage Resistance | F40: 剛毅 Toughness | G40: 武器天賦 Weapon Aptitude | H40: 黑暗視覺 Darkvision | I40: 毒素韌性 Poison Resilience | J40: 盤石 Steady | K40: 匠人專精 Artisanal Focus | L40: 工匠之眼 Crafter's Eye
...

Sheet 子職業能力
A1: 職業等級 | B1: 子職業類型 | C1: 能力A | D1: 能力B | E1: 能力C | F1: 能力D | G1: 能力E | H1: 能力F | I1: 能力G | J1: 能力H
A2: ='職業能力'!B2 -> 0 | B2: 狂戰士道途 | C2: =IF(A2>=1,"狂怒("&IF(A2>=16,"4d6",IF(A2>=9,"3d6","2d6"))&")","") | D2: =IF($A$2>=6,"無我狂暴","") | E2: =IF($A$2>=10,"復仇","") | F2: =IF($A$2>=14,"威攝之姿","")
A3: 野蠻人 | B3: 荒野之心道途 | C3: =IF($A$2>=3,"動物語者","") | D3: =IF($A$2>=3,"獸性狂暴","") | E3: =IF($A$2>=6,"獸體形貌"&'職業能力選項'!F3,"") | F3: =IF($A$2>=10,"自然語者","") | G3: =IF($A$2>=14,"獸力威能","")
B4: 世界樹道途 | C4: =IF($A$2>=3,"聖樹活力","") | D4: =IF($A$2>=6,"靈樹枝枒","") | E4: =IF($A$2>=10,"根擊千鈞","") | F4: =IF($A$2>=14,"世界樹奇旅","")
B5: 狂熱者道途 | C5: =IF($A$2>=3,"神性之怒","") | D5: =IF($A$2>=3,"諸神勇士","") | E5: =IF($A$2>=6,"狂熱專注","") | F5: =IF($A$2>=10,"狂熱威儀","") | G5: =IF($A$2>=14,"神祗狂暴","")
B6: 實驗道途 | C6: =IF($A$2>=3,"煉金實驗","") | D6: =IF($A$2>=3,"不穩定血清","") | E6: =IF($A$2>=6,"強化化合物","") | F6: =IF($A$2>=10,"應激催化","") | G6: =IF($A$2>=14,"生化混合","")
B7: 肌肉魔法使道途 | C7: =IF($A$2>=3,"無'法'反駁","") | D7: =IF($A$2>=3,"「戲法」","") | E7: =IF($A$2>=3,"「法術」","") | F7: =IF($A$2>=3,"魔法抗性","") | G7: =IF($A$2>=3,"我施放拳頭","")
B8: 蔑法道途 | C8: =IF($A$2>=3,"本能預知","") | D8: =IF($A$2>=3,"破法槌","") | E8: =IF($A$2>=3,"吸法盾","") | F8: =IF($A$2>=6,"撕裂魔網","") | G8: =IF($A$2>=10,"振奮咆哮","") | H8: =IF($A$2>=14,"次元決鬥","")
B9: 分裂道途 | C9: =IF($A$2>=3,"狂怒面容","") | D9: =IF($A$2>=3,"文明面具","") | E9: =IF($A$2>=6,"智慧與力量","") | F9: =IF($A$2>=10,"狡詐與殘暴","") | G9: =IF($A$2>=14,"另一個我","")
B10: 原初精魂道途 | C10: =IF($A$2>=3,"原初夥伴","") | D10: =IF($A$2>=3,"共享狂暴","") | E10: =IF($A$2>=3,"野獸親族","") | F10: =IF($A$2>=3,"獸魂附體","") | G10: =IF($A$2>=3,"荒野之形","")
B11: 憤怒亡靈道途 | C11: =IF($A$2>=3,"亡靈之怒","") | D11: =IF($A$2>=3,"終夜宣洩"&'職業能力選項'!F6,"") | E11: =IF($A$2>=6,"重演黑暗厄運","") | F11: =IF($A$2>=10,"死亡不過是一扇門","") | G11: =IF($A$2>=14,"悲愴驅動","")
B12: 冰川道途 | C12: =IF($A$2>=3,"原初霜寒","") | D12: =IF($A$2>=3,"霜噬","") | E12: =IF($A$2>=3,"寒霜壁壘","") | F12: =IF($A$2>=3,"深度睡眠","") | G12: =IF($A$2>=3,"雪崩踏步","")
A24: ='職業能力'!C2 -> 0 | B24: 舞蹈學院 | C24: =IF($A$24>=3,"炫目舞步","") | D24: =IF($A$24>=6,"激勵移動","") | E24: =IF($A$24>=6,"協同舞步","") | F24: =IF($A$24>=14,"引導閃避","")
A25: 吟遊詩人 | B25: 迷惑學院 | C25: =IF($A$24>=3,"惑心魔法","") | D25: =IF($A$24>=3,"鼓舞領域","") | E25: =IF($A$24>=6,"威嚴領域","") | F25: =IF($A$24>=14,"絕對威儀","")
B26: 軼聞學院 | C26: =IF($A$24>=3,"額外熟練","") | D26: =IF($A$24>=3,"語出驚人","") | E26: =IF($A$24>=6,"魔法發現","") | F26: =IF($A$24>=14,"絕代技能","")
B27: 勇氣學院 | C27: =IF($A$24>=3,"戰鬥激勵","") | D27: =IF($A$24>=3,"武術訓練","") | E27: =IF($A$24>=6,"額外攻擊","") | F27: =IF($A$24>=14,"戰鬥魔法","")
B28: 月亮學院 | C28: =IF($A$24>=3,"明月激勵","") | D28: =IF($A$24>=3,"原初軼聞","") | E28: =IF($A$24>=6,"月光祝福","") | F28: =IF($A$24>=14,"暮光輝映","")
B29: 靈哨學院 | C29: =IF($A$24>=3,"助人鬼祟","") | D29: =IF($A$24>=3,"吹哨漫遊者","") | E29: =IF($A$24>=6,"歸鄉之路","") | F29: =IF($A$24>=6,"軌道疾行","") | G29: =IF($A$24>=14,"終點站","")
B30: 戲劇學院 | C30: =IF($A$24>=3,"悲劇英雄","") | D30: =IF($A$24>=3,"百面人生","") | E30: =IF($A$24>=6,"舞台指導","") | F30: =IF($A$24>=6,"眾星登場","") | G30: =IF($A$24>=14,"壓軸好戲","")
B31: 冒險者學院 | C31: =IF($A$24>=3,"冒險者天賦("&IF(A91>=14,"3項",IF(A91>=6,"2項","1項"))&")","") | D31: =IF($A$24>=3,"團隊策劃","") | E31: =IF($A$24>=6,"面面俱到","") | F31: =IF($A$24>=14,"即興天賦","")
B32: 弄臣學院 | C32: =IF($A$24>=3,"丑態挑釁","") | D32: =IF($A$24>=3,"惡毒戲謔","") | E32: =IF($A$24>=6,"黑色幽默","") | F32: =IF($A$24>=14,"笑到最後","")
B33: 安魂學院 | C33: =IF($A$24>=3,"寒顫旋律","") | D33: =IF($A$24>=3,"撥動心弦","") | E33: =IF($A$24>=6,"舞動骸骨","") | F33: =IF($A$24>=14,"雙死","")
B34: 傳頌學院 | C34: =IF($A$24>=3,"廣泛激勵","") | D34: =IF($A$24>=3,"歷史守護者","") | E34: =IF($A$24>=6,"命令之聲","") | F34: =IF($A$24>=14,"戰鬥頌歌","")
B35: 織舞學院 | C35: =IF($A$24>=3,"快速移動","") | D35: =IF($A$24>=3,"激勵舞蹈","") | E35: =IF($A$24>=6,"迷人步伐","") | F35: =IF($A$24>=14,"無盡之舞","")
A46: ='職業能力'!D2 -> 0 | B46: 生命領域 | C46: =IF($A$46>=3,"生命領域法術","") | D46: =IF($A$46>=3,"生命門徒","") | E46: =IF($A$46>=3,"引導神力：維繫生命","") | F46: =IF($A$46>=6,"祝聖醫者","") | G46: =IF($A$46>=17,"極效治療","")
A47: 牧師 | B47: 光明領域 | C47: =IF($A$46>=3,"光明領域法術","") | D47: =IF($A$46>=3,"閃耀防護","") | E47: =IF($A$46>=3,"引導神力：黎明曙光","") | F47: =IF($A$46>=6,"強化閃耀防護","") | G47: =IF($A$46>=17,"日冕光輝","")
B48: 詭術領域 | C48: =IF($A$46>=3,"詭術領域法術","") | D48: =IF($A$46>=3,"詭術祝福","") | E48: =IF($A$46>=3,"引導神力：召喚分身","") | F48: =IF($A$46>=6,"詭詐換位","") | G48: =IF($A$46>=17,"強化分身","")
B49: 戰爭領域 | C49: =IF($A$46>=3,"戰爭領域法術","") | D49: =IF($A$46>=3,"戰爭祭司","") | E49: =IF($A$46>=3,"引導神力：導引打擊","") | F49: =IF($A$46>=6,"引導神力：戰神祝福","") | G49: =IF($A$46>=17,"戰爭化身","")
B50: 知識領域 | C50: =IF($A$46>=3,"知識領域法術","") | D50: =IF($A$46>=3,"知識祝福","") | E50: =IF($A$46>=3,"引導神力：思維魔法","") | F50: =IF($A$46>=6,"無拘思維","") | G50: =IF($A$46>=17,"神聖預知","")
B51: 豐收領域 | C51: =IF($A$46>=3,"豐收領域法術","") | D51: =IF($A$46>=3,"農民曆","") | E51: =IF($A$46>=3,"豐裕之角","") | F51: =IF($A$46>=3,"引導神力：五穀豐登","") | G51: =IF($A$46>=6,"四季祝福","") | H51: =IF($A$46>=17,"永恆之輪","")
B52: 天啟領域 | C52: =IF($A$46>=3,"天啟領域法術","") | D52: =IF($A$46>=3,"毀滅願景","") | E52: =IF($A$46>=3,"引導神力：末日之歌","") | F52: =IF($A$46>=6,"塵歸塵，土歸土","") | G52: =IF($A$46>=17,"浩劫餘生","")
B53: 怪異領域 | C53: =IF($A$46>=3,"怪異領域法術","") | D53: =IF($A$46>=3,"怪異蔓延","") | E53: =IF($A$46>=3,"引導神力：厄運預言","") | F53: =IF($A$46>=6,"超凡鎮定","") | G53: =IF($A$46>=17,"吟唱終末之歌","")
B54: 審判領域 | C54: =IF($A$46>=3,"審判領域法術","") | D54: =IF($A$46>=3,"獵巫打擊","") | E54: =IF($A$46>=3,"引導神力：法術護盾","") | F54: =IF($A$46>=6,"叱喝祈者","") | G54: =IF($A$46>=17,"至高守護","")
B55: 淨化領域 | C55: =IF($A$46>=3,"淨化領域法術","") | D55: =IF($A$46>=3,"以火淨化","") | E55: =IF($A$46>=3,"引導神力：不潔烙印","") | F55: =IF($A$46>=6,"防止腐化","") | G55: =IF($A$46>=17,"燒灼瑕疵","")
B56: 心靈領域 | C56: =IF($A$46>=3,"心靈領域法術","") | D56: =IF($A$46>=3,"精神之力","") | E56: =IF($A$46>=3,"引導神力：精神反饋","") | F56: =IF($A$46>=6,"格式塔定錨","") | G56: =IF($A$46>=17,"現實連結","")
B57: 星界領域 | C57: =IF($A$46>=3,"星界領域法術","") | D57: =IF($A$46>=3,"位面觸碰","") | E57: =IF($A$46>=3,"引導神力：創造虛空","") | F57: =IF($A$46>=6,"空間交換","") | G57: =IF($A$46>=17,"卓越替換","")
A68: ='職業能力'!E2 -> 0 | B68: 大地結社 | C68: =IF($A$68>=3,"大地結社法術"&'職業能力選項'!T3,"") | D68: =IF($A$68>=3,"大地援助","") | E68: =IF($A$68>=6,"自然恢復","") | F68: =IF($A$68>=10,"自然加護"&'職業能力選項'!U3,"") | G68: =IF($A$68>=14,"自然庇護","")
